Workbook

Sheet CPI_Downloader
A1: Date | B1: Headline CPI - Unadjusted CDN | C1: Headline CPI - Seasonally Adjusted CDN | D1: Core CPI - Unadjusted CDN | E1: Core CPI - Seasonally Adjusted CDN | F1: Alberta CPI - Unadjusted CDN | G1: Headline CPI - Unadjusted US | H1: Headline CPI - Seasonally Adjusted US | I1: Core CPI - Unadjusted US | J1: Core CPI - Seasonally Adjusted US | K1: Unemployment Rate - Seasonally Adjusted US | L1: Monthly Effective Fed Fund Rate US | M1: Monthly Fed Fund Rate - EOP US | N1: SP by month US | O1: 10yr vs 2yr US | P1: PCE - Seasonally Adjusted US | Q1: Core PCE - Seasonally Adjusted US
A2: 4750 | G2: 9.8
A3: 4781 | G3: 9.8
A4: 4809 | G4: 9.8
A5: 4840 | G5: 9.8
A6: 4870 | G6: 9.7
A7: 4901 | G7: 9.8
A8: 4931 | G8: 9.9
A9: 4962 | G9: 9.9
A10: 4993 | G10: 10
A11: 5023 | G11: 10
A12: 5054 | G12: 10.1
A13: 5084 | G13: 10
A14: 5115 | B14: 6 | G14: 10
A15: 5146 | B15: 6 | G15: 9.9
A16: 5174 | B16: 6 | G16: 9.9
A17: 5205 | B17: 6 | G17: 9.8
A18: 5235 | B18: 5.9 | G18: 9.9
A19: 5266 | B19: 6 | G19: 9.9
A20: 5296 | B20: 5.9 | G20: 10
A21: 5327 | B21: 6 | G21: 10.2
A22: 5358 | B22: 6 | G22: 10.2
A23: 5388 | B23: 6.1 | G23: 10.1
A24: 5419 | B24: 6.1 | G24: 10.2
A25: 5449 | B25: 6.1 | G25: 10.1
... A409: 17137 | B409: 9.7 | G409: 21.5
A410: 17168 | B410: 9.7 | G410: 21.5 | H410: 21.48
A411: 17199 | B411: 9.7 | G411: 21.5 | H411: 21.62
A412: 17227 | B412: 9.8 | G412: 21.9 | H412: 22
A413: 17258 | B413: 9.9 | G413: 21.9 | H413: 22
A414: 17288 | B414: 10.1 | G414: 21.9 | H414: 21.95
A415: 17319 | B415: 10.2 | G415: 22 | H415: 22.08
A416: 17349 | B416: 10.3 | G416: 22.2 | H416: 22.23
A417: 17380 | B417: 10.3 | G417: 22.5 | H417: 22.4
A418: 17411 | B418: 10.6 | G418: 23 | H418: 22.84
A419: 17441 | B419: 10.8 | G419: 23 | H419: 22.91
A420: 17472 | B420: 10.9 | G420: 23.1 | H420: 23.06
A421: 17502 | B421: 11.1 | G421: 23.4 | H421: 23.41
A422: 17533 | B422: 11.2 | G422: 23.7 | H422: 23.68 | K422: 3.4
A423: 17564 | B423: 11.4 | G423: 23.5 | H423: 23.67 | K423: 3.8
...

Sheet US Headline Inflation 1

Sheet CDN Headline Inflation 1

Sheet CDN Core Inflation 1

Sheet US Core Inflation 1

Sheet Historical Recessions 1

Sheet US Data
A1: SA = Seasonally Adjusted | B1: Headline = All items | D1: Note: Each year, for the January CPI release, the seasonal adjustment factors are recalculated for the previous 5 years. https://www.bls.gov/cpi/seasonal-adjustment/home.htm | I1: https://fred.stlouisfed.org/tags/series?t=cbsa%3Bcpi&rt=cbsa&ob=pv&od=desc | M1: Core = Food/Energy excluded | T1: https://fred.stlouisfed.org/series/CPILFESL | AA1: UL = Upper limit (Ceiling) | AB1: https://fred.stlouisfed.org/series/FEDFUNDS | AE1: 0% = No recession | AF1: National Bureau of Economic Research | AG1: https://en.wikipedia.org/wiki/List_of_recessions_in_the_United_States
A2: U - Unadjusted | I2: https://fred.stlouisfed.org/series/CPIAUCNS | J2: https://fred.stlouisfed.org/series/CPIAUCSL | T2: https://fred.stlouisfed.org/series/CPILFENS | W2: NOTE: MAY NOT MATCH AS SA | X2: https://fred.stlouisfed.org/series/UNRATE | AA2: EOP = End of Period | AB2: https://fred.stlouisfed.org/series/DFEDTARU | AE2: 100% = recession | AF2: https://www.whitehouse.gov/cea/written-materials/2022/07/21/how-do-economists-determine-whether-the-economy-is-in-a-recession/ | AL2: https://fred.stlouisfed.org/series/T10Y2Y | AT2: https://fred.stlouisfed.org/series/PCEPI | BA2: https://fred.stlouisfed.org/series/PCEPILFE
A3: Month | B3: Annual Headline CPI - U | C3: Monthly Headline CPI - SA | D3: 3yr Headline CPI - U | E3: 5yr Headline CPI - U | F3: 10yr Headline CPI - U | G3: 20yr Headline CPI - U | H3: CDN Annual Headline CPI - U | I3: US Headline CPI - U - DATA | J3: US Headline CPI - SA - DATA | L3: Month | M3: Annual Core CPI - U | N3: Monthly Core CPI - SA | O3: 3yr Core CPI - U | P3: 5yr Core CPI - U | Q3: 10yr Core CPI - U | R3: 20yr Core CPI - U | S3: CDN Annual Core CPI - U | T3: Core CPI - U - DATA | U3: Core CPI - SA - DATA | W3: Annual Unemployment - SA | X3: Monthly Unemployment - SA | Y3: Unemployment Rate - SA - DATA | AA3: Monthly Fed Fund Rate - EOP | AB3: Monthly Fed Fund Rate - EOP - DATA | AC3: Monthly Effective Fed Fund Rate | AE3: US Recessions (per NBER) (https://www.nber.org/research/data/us-business-cycle-expansions-and-contractions) | AI3: S&P % by month | AJ3: S&P 500 (EOM) | AK3: https://fred.stlouisfed.org/series/SP500#0 | AL3: 10yr vs 2yr | AN3: Annual Headline PCE | AO3: Monthly Headline PCE | AP3: 3yr Headline PCE | AQ3: 5yr Headline PCE | AR3: 10yr Headline PCE | AS3: 20yr Headline PCE | AT3: PCE - SA | AU3: Annual Headline PCE | AV3: Monthly Headline PCE | AW3: 3yr Headline PCE | AX3: 5yr Headline PCE | AY3: 10yr Headline PCE | AZ3: 20yr Headline PCE | BA3: Core PCE - SA
A4: =IF(CPI_Downloader!A2="","",CPI_Downloader!A2) -> 4750 | C4: =IFERROR((J4/J3-1),"") | H4: =IF('CDN Data'!B4=0,"",IFERROR(('CDN Data'!B4),"")) | I4: =IF(CPI_Downloader!G2="","",CPI_Downloader!G2) -> 9.8 | J4: =IF(CPI_Downloader!H2="","",CPI_Downloader!H2) | L4: =A4 -> 4750 | T4: =IF(CPI_Downloader!I2="","",CPI_Downloader!I2) | U4: =IF(CPI_Downloader!J2="","",CPI_Downloader!J2) | X4: =IFERROR((Y4/100),"") | Y4: =IF(CPI_Downloader!K2="","",CPI_Downloader!K2) | AA4: =IFERROR((AB4/100),"") | AB4: =IF(CPI_Downloader!M2="","",CPI_Downloader!M2) | AC4: =IF(CPI_Downloader!L2="","",CPI_Downloader!L2/100) | AE4: 1 | AJ4: =IF(CPI_Downloader!N2="","",CPI_Downloader!N2) | AL4: =IF(CPI_Downloader!O2="","",CPI_Downloader!O2) | AT4: =IF(CPI_Downloader!P2="","",CPI_Downloader!P2) | BA4: =IF(CPI_Downloader!Q2="","",CPI_Downloader!Q2)
A5: =IF(CPI_Downloader!A3="","",CPI_Downloader!A3) -> 4781 | C5: =IFERROR((J5/J4-1),"") | H5: =IF('CDN Data'!B5=0,"",IFERROR(('CDN Data'!B5),"")) | I5: =IF(CPI_Downloader!G3="","",CPI_Downloader!G3) -> 9.8 | J5: =IF(CPI_Downloader!H3="","",CPI_Downloader!H3) | L5: =A5 -> 4781 | T5: =IF(CPI_Downloader!I3="","",CPI_Downloader!I3) | U5: =IF(CPI_Downloader!J3="","",CPI_Downloader!J3) | X5: =IFERROR((Y5/100),"") | Y5: =IF(CPI_Downloader!K3="","",CPI_Downloader!K3) | AA5: =IFERROR((AB5/100),"") | AB5: =IF(CPI_Downloader!M3="","",CPI_Downloader!M3) | AC5: =IF(CPI_Downloader!L3="","",CPI_Downloader!L3/100) | AE5: 1 | AI5: =IFERROR((AJ5/AJ4-1),"") | AJ5: =IF(CPI_Downloader!N3="","",CPI_Downloader!N3) | AL5: =IF(CPI_Downloader!O3="","",CPI_Downloader!O3) | AO5: =IFERROR((AT5/AT4-1),"") | AT5: =IF(CPI_Downloader!P3="","",CPI_Downloader!P3) | AV5: =IFERROR((BA5/BA4-1),"") | BA5: =IF(CPI_Downloader!Q3="","",CPI_Downloader!Q3)
A6: =IF(CPI_Downloader!A4="","",CPI_Downloader!A4) -> 4809 | C6: =IFERROR((J6/J5-1),"") | H6: =IF('CDN Data'!B6=0,"",IFERROR(('CDN Data'!B6),"")) | I6: =IF(CPI_Downloader!G4="","",CPI_Downloader!G4) -> 9.8 | J6: =IF(CPI_Downloader!H4="","",CPI_Downloader!H4) | L6: =A6 -> 4809 | T6: =IF(CPI_Downloader!I4="","",CPI_Downloader!I4) | U6: =IF(CPI_Downloader!J4="","",CPI_Downloader!J4) | X6: =IFERROR((Y6/100),"") | Y6: =IF(CPI_Downloader!K4="","",CPI_Downloader!K4) | AA6: =IFERROR((AB6/100),"") | AB6: =IF(CPI_Downloader!M4="","",CPI_Downloader!M4) | AC6: =IF(CPI_Downloader!L4="","",CPI_Downloader!L4/100) | AE6: 1 | AI6: =IFERROR((AJ6/AJ5-1),"") | AJ6: =IF(CPI_Downloader!N4="","",CPI_Downloader!N4) | AL6: =IF(CPI_Downloader!O4="","",CPI_Downloader!O4) | AO6: =IFERROR((AT6/AT5-1),"") | AT6: =IF(CPI_Downloader!P4="","",CPI_Downloader!P4) | AV6: =IFERROR((BA6/BA5-1),"") | BA6: =IF(CPI_Downloader!Q4="","",CPI_Downloader!Q4)
A7: =IF(CPI_Downloader!A5="","",CPI_Downloader!A5) -> 4840 | C7: =IFERROR((J7/J6-1),"") | H7: =IF('CDN Data'!B7=0,"",IFERROR(('CDN Data'!B7),"")) | I7: =IF(CPI_Downloader!G5="","",CPI_Downloader!G5) -> 9.8 | J7: =IF(CPI_Downloader!H5="","",CPI_Downloader!H5) | L7: =A7 -> 4840 | T7: =IF(CPI_Downloader!I5="","",CPI_Downloader!I5) | U7: =IF(CPI_Downloader!J5="","",CPI_Downloader!J5) | X7: =IFERROR((Y7/100),"") | Y7: =IF(CPI_Downloader!K5="","",CPI_Downloader!K5) | AA7: =IFERROR((AB7/100),"") | AB7: =IF(CPI_Downloader!M5="","",CPI_Downloader!M5) | AC7: =IF(CPI_Downloader!L5="","",CPI_Downloader!L5/100) | AE7: 1 | AI7: =IFERROR((AJ7/AJ6-1),"") | AJ7: =IF(CPI_Downloader!N5="","",CPI_Downloader!N5) | AL7: =IF(CPI_Downloader!O5="","",CPI_Downloader!O5) | AO7: =IFERROR((AT7/AT6-1),"") | AT7: =IF(CPI_Downloader!P5="","",CPI_Downloader!P5) | AV7: =IFERROR((BA7/BA6-1),"") | BA7: =IF(CPI_Downloader!Q5="","",CPI_Downloader!Q5)
A8: =IF(CPI_Downloader!A6="","",CPI_Downloader!A6) -> 4870 | C8: =IFERROR((J8/J7-1),"") | H8: =IF('CDN Data'!B8=0,"",IFERROR(('CDN Data'!B8),"")) | I8: =IF(CPI_Downloader!G6="","",CPI_Downloader!G6) -> 9.7 | J8: =IF(CPI_Downloader!H6="","",CPI_Downloader!H6) | L8: =A8 -> 4870 | T8: =IF(CPI_Downloader!I6="","",CPI_Downloader!I6) | U8: =IF(CPI_Downloader!J6="","",CPI_Downloader!J6) | X8: =IFERROR((Y8/100),"") | Y8: =IF(CPI_Downloader!K6="","",CPI_Downloader!K6) | AA8: =IFERROR((AB8/100),"") | AB8: =IF(CPI_Downloader!M6="","",CPI_Downloader!M6) | AC8: =IF(CPI_Downloader!L6="","",CPI_Downloader!L6/100) | AE8: 1 | AI8: =IFERROR((AJ8/AJ7-1),"") | AJ8: =IF(CPI_Downloader!N6="","",CPI_Downloader!N6) | AL8: =IF(CPI_Downloader!O6="","",CPI_Downloader!O6) | AO8: =IFERROR((AT8/AT7-1),"") | AT8: =IF(CPI_Downloader!P6="","",CPI_Downloader!P6) | AV8: =IFERROR((BA8/BA7-1),"") | BA8: =IF(CPI_Downloader!Q6="","",CPI_Downloader!Q6)
A9: =IF(CPI_Downloader!A7="","",CPI_Downloader!A7) -> 4901 | C9: =IFERROR((J9/J8-1),"") | H9: =IF('CDN Data'!B9=0,"",IFERROR(('CDN Data'!B9),"")) | I9: =IF(CPI_Downloader!G7="","",CPI_Downloader!G7) -> 9.8 | J9: =IF(CPI_Downloader!H7="","",CPI_Downloader!H7) | L9: =A9 -> 4901 | N9: =IFERROR((U9/U8-1),"") | T9: =IF(CPI_Downloader!I7="","",CPI_Downloader!I7) | U9: =IF(CPI_Downloader!J7="","",CPI_Downloader!J7) | X9: =IFERROR((Y9/100),"") | Y9: =IF(CPI_Downloader!K7="","",CPI_Downloader!K7) | AA9: =IFERROR((AB9/100),"") | AB9: =IF(CPI_Downloader!M7="","",CPI_Downloader!M7) | AC9: =IF(CPI_Downloader!L7="","",CPI_Downloader!L7/100) | AE9: 1 | AI9: =IFERROR((AJ9/AJ8-1),"") | AJ9: =IF(CPI_Downloader!N7="","",CPI_Downloader!N7) | AL9: =IF(CPI_Downloader!O7="","",CPI_Downloader!O7) | AO9: =IFERROR((AT9/AT8-1),"") | AT9: =IF(CPI_Downloader!P7="","",CPI_Downloader!P7) | AV9: =IFERROR((BA9/BA8-1),"") | BA9: =IF(CPI_Downloader!Q7="","",CPI_Downloader!Q7)
A10: =IF(CPI_Downloader!A8="","",CPI_Downloader!A8) -> 4931 | C10: =IFERROR((J10/J9-1),"") | H10: =IF('CDN Data'!B10=0,"",IFERROR(('CDN Data'!B10),"")) | I10: =IF(CPI_Downloader!G8="","",CPI_Downloader!G8) -> 9.9 | J10: =IF(CPI_Downloader!H8="","",CPI_Downloader!H8) | L10: =A10 -> 4931 | N10: =IFERROR((U10/U9-1),"") | T10: =IF(CPI_Downloader!I8="","",CPI_Downloader!I8) | U10: =IF(CPI_Downloader!J8="","",CPI_Downloader!J8) | X10: =IFERROR((Y10/100),"") | Y10: =IF(CPI_Downloader!K8="","",CPI_Downloader!K8) | AA10: =IFERROR((AB10/100),"") | AB10: =IF(CPI_Downloader!M8="","",CPI_Downloader!M8) | AC10: =IF(CPI_Downloader!L8="","",CPI_Downloader!L8/100) | AE10: 1 | AI10: =IFERROR((AJ10/AJ9-1),"") | AJ10: =IF(CPI_Downloader!N8="","",CPI_Downloader!N8) | AL10: =IF(CPI_Downloader!O8="","",CPI_Downloader!O8) | AO10: =IFERROR((AT10/AT9-1),"") | AT10: =IF(CPI_Downloader!P8="","",CPI_Downloader!P8) | AV10: =IFERROR((BA10/BA9-1),"") | BA10: =IF(CPI_Downloader!Q8="","",CPI_Downloader!Q8)
A11: =IF(CPI_Downloader!A9="","",CPI_Downloader!A9) -> 4962 | C11: =IFERROR((J11/J10-1),"") | H11: =IF('CDN Data'!B11=0,"",IFERROR(('CDN Data'!B11),"")) | I11: =IF(CPI_Downloader!G9="","",CPI_Downloader!G9) -> 9.9 | J11: =IF(CPI_Downloader!H9="","",CPI_Downloader!H9) | L11: =A11 -> 4962 | N11: =IFERROR((U11/U10-1),"") | T11: =IF(CPI_Downloader!I9="","",CPI_Downloader!I9) | U11: =IF(CPI_Downloader!J9="","",CPI_Downloader!J9) | X11: =IFERROR((Y11/100),"") | Y11: =IF(CPI_Downloader!K9="","",CPI_Downloader!K9) | AA11: =IFERROR((AB11/100),"") | AB11: =IF(CPI_Downloader!M9="","",CPI_Downloader!M9) | AC11: =IF(CPI_Downloader!L9="","",CPI_Downloader!L9/100) | AE11: 1 | AI11: =IFERROR((AJ11/AJ10-1),"") | AJ11: =IF(CPI_Downloader!N9="","",CPI_Downloader!N9) | AL11: =IF(CPI_Downloader!O9="","",CPI_Downloader!O9) | AO11: =IFERROR((AT11/AT10-1),"") | AT11: =IF(CPI_Downloader!P9="","",CPI_Downloader!P9) | AV11: =IFERROR((BA11/BA10-1),"") | BA11: =IF(CPI_Downloader!Q9="","",CPI_Downloader!Q9)
A12: =IF(CPI_Downloader!A10="","",CPI_Downloader!A10) -> 4993 | C12: =IFERROR((J12/J11-1),"") | H12: =IF('CDN Data'!B12=0,"",IFERROR(('CDN Data'!B12),"")) | I12: =IF(CPI_Downloader!G10="","",CPI_Downloader!G10) -> 10 | J12: =IF(CPI_Downloader!H10="","",CPI_Downloader!H10) | L12: =A12 -> 4993 | N12: =IFERROR((U12/U11-1),"") | T12: =IF(CPI_Downloader!I10="","",CPI_Downloader!I10) | U12: =IF(CPI_Downloader!J10="","",CPI_Downloader!J10) | X12: =IFERROR((Y12/100),"") | Y12: =IF(CPI_Downloader!K10="","",CPI_Downloader!K10) | AA12: =IFERROR((AB12/100),"") | AB12: =IF(CPI_Downloader!M10="","",CPI_Downloader!M10) | AC12: =IF(CPI_Downloader!L10="","",CPI_Downloader!L10/100) | AE12: 1 | AI12: =IFERROR((AJ12/AJ11-1),"") | AJ12: =IF(CPI_Downloader!N10="","",CPI_Downloader!N10) | AL12: =IF(CPI_Downloader!O10="","",CPI_Downloader!O10) | AO12: =IFERROR((AT12/AT11-1),"") | AT12: =IF(CPI_Downloader!P10="","",CPI_Downloader!P10) | AV12: =IFERROR((BA12/BA11-1),"") | BA12: =IF(CPI_Downloader!Q10="","",CPI_Downloader!Q10)
A13: =IF(CPI_Downloader!A11="","",CPI_Downloader!A11) -> 5023 | C13: =IFERROR((J13/J12-1),"") | H13: =IF('CDN Data'!B13=0,"",IFERROR(('CDN Data'!B13),"")) | I13: =IF(CPI_Downloader!G11="","",CPI_Downloader!G11) -> 10 | J13: =IF(CPI_Downloader!H11="","",CPI_Downloader!H11) | L13: =A13 -> 5023 | N13: =IFERROR((U13/U12-1),"") | T13: =IF(CPI_Downloader!I11="","",CPI_Downloader!I11) | U13: =IF(CPI_Downloader!J11="","",CPI_Downloader!J11) | X13: =IFERROR((Y13/100),"") | Y13: =IF(CPI_Downloader!K11="","",CPI_Downloader!K11) | AA13: =IFERROR((AB13/100),"") | AB13: =IF(CPI_Downloader!M11="","",CPI_Downloader!M11) | AC13: =IF(CPI_Downloader!L11="","",CPI_Downloader!L11/100) | AE13: 1 | AI13: =IFERROR((AJ13/AJ12-1),"") | AJ13: =IF(CPI_Downloader!N11="","",CPI_Downloader!N11) | AL13: =IF(CPI_Downloader!O11="","",CPI_Downloader!O11) | AO13: =IFERROR((AT13/AT12-1),"") | AT13: =IF(CPI_Downloader!P11="","",CPI_Downloader!P11) | AV13: =IFERROR((BA13/BA12-1),"") | BA13: =IF(CPI_Downloader!Q11="","",CPI_Downloader!Q11)
A14: =IF(CPI_Downloader!A12="","",CPI_Downloader!A12) -> 5054 | C14: =IFERROR((J14/J13-1),"") | H14: =IF('CDN Data'!B14=0,"",IFERROR(('CDN Data'!B14),"")) | I14: =IF(CPI_Downloader!G12="","",CPI_Downloader!G12) -> 10.1 | J14: =IF(CPI_Downloader!H12="","",CPI_Downloader!H12) | L14: =A14 -> 5054 | N14: =IFERROR((U14/U13-1),"") | T14: =IF(CPI_Downloader!I12="","",CPI_Downloader!I12) | U14: =IF(CPI_Downloader!J12="","",CPI_Downloader!J12) | X14: =IFERROR((Y14/100),"") | Y14: =IF(CPI_Downloader!K12="","",CPI_Downloader!K12) | AA14: =IFERROR((AB14/100),"") | AB14: =IF(CPI_Downloader!M12="","",CPI_Downloader!M12) | AC14: =IF(CPI_Downloader!L12="","",CPI_Downloader!L12/100) | AE14: 1 | AI14: =IFERROR((AJ14/AJ13-1),"") | AJ14: =IF(CPI_Downloader!N12="","",CPI_Downloader!N12) | AL14: =IF(CPI_Downloader!O12="","",CPI_Downloader!O12) | AO14: =IFERROR((AT14/AT13-1),"") | AT14: =IF(CPI_Downloader!P12="","",CPI_Downloader!P12) | AV14: =IFERROR((BA14/BA13-1),"") | BA14: =IF(CPI_Downloader!Q12="","",CPI_Downloader!Q12)
A15: =IF(CPI_Downloader!A13="","",CPI_Downloader!A13) -> 5084 | C15: =IFERROR((J15/J14-1),"") | H15: =IF('CDN Data'!B15=0,"",IFERROR(('CDN Data'!B15),"")) | I15: =IF(CPI_Downloader!G13="","",CPI_Downloader!G13) -> 10 | J15: =IF(CPI_Downloader!H13="","",CPI_Downloader!H13) | L15: =A15 -> 5084 | N15: =IFERROR((U15/U14-1),"") | T15: =IF(CPI_Downloader!I13="","",CPI_Downloader!I13) | U15: =IF(CPI_Downloader!J13="","",CPI_Downloader!J13) | W15: =IFERROR((AVERAGE(Y4:Y15)/100),"") | X15: =IFERROR((Y15/100),"") | Y15: =IF(CPI_Downloader!K13="","",CPI_Downloader!K13) | AA15: =IFERROR((AB15/100),"") | AB15: =IF(CPI_Downloader!M13="","",CPI_Downloader!M13) | AC15: =IF(CPI_Downloader!L13="","",CPI_Downloader!L13/100) | AE15: 1 | AI15: =IFERROR((AJ15/AJ14-1),"") | AJ15: =IF(CPI_Downloader!N13="","",CPI_Downloader!N13) | AL15: =IF(CPI_Downloader!O13="","",CPI_Downloader!O13) | AO15: =IFERROR((AT15/AT14-1),"") | AT15: =IF(CPI_Downloader!P13="","",CPI_Downloader!P13) | AV15: =IFERROR((BA15/BA14-1),"") | BA15: =IF(CPI_Downloader!Q13="","",CPI_Downloader!Q13)
A16: =IF(CPI_Downloader!A14="","",CPI_Downloader!A14) -> 5115 | B16: =IFERROR((I16/I4-1),"") -> 0.020408163 | C16: =IFERROR((J16/J15-1),"") | H16: =IFERROR(('CDN Data'!B16),"") | I16: =IF(CPI_Downloader!G14="","",CPI_Downloader!G14) -> 10 | J16: =IF(CPI_Downloader!H14="","",CPI_Downloader!H14) | L16: =A16 -> 5115 | M16: =IFERROR((T16/T4-1),"") | N16: =IFERROR((U16/U15-1),"") | S16: =IF('CDN Data'!M4=0,"",IFERROR(('CDN Data'!M4),"")) | T16: =IF(CPI_Downloader!I14="","",CPI_Downloader!I14) | U16: =IF(CPI_Downloader!J14="","",CPI_Downloader!J14) | W16: =IFERROR((AVERAGE(Y5:Y16)/100),"") | X16: =IFERROR((Y16/100),"") | Y16: =IF(CPI_Downloader!K14="","",CPI_Downloader!K14) | AA16: =IFERROR((AB16/100),"") | AB16: =IF(CPI_Downloader!M14="","",CPI_Downloader!M14) | AC16: =IF(CPI_Downloader!L14="","",CPI_Downloader!L14/100) | AE16: 1 | AI16: =IFERROR((AJ16/AJ15-1),"") | AJ16: =IF(CPI_Downloader!N14="","",CPI_Downloader!N14) | AL16: =IF(CPI_Downloader!O14="","",CPI_Downloader!O14) | AN16: =IFERROR((AT16/AT4-1),"") | AO16: =IFERROR((AT16/AT15-1),"") | AT16: =IF(CPI_Downloader!P14="","",CPI_Downloader!P14) | AU16: =IFERROR((BA16/BA4-1),"") | AV16: =IFERROR((BA16/BA15-1),"") | BA16: =IF(CPI_Downloader!Q14="","",CPI_Downloader!Q14)
A17: =IF(CPI_Downloader!A15="","",CPI_Downloader!A15) -> 5146 | B17: =IFERROR((I17/I5-1),"") -> 0.010204082 | C17: =IFERROR((J17/J16-1),"") | H17: =IFERROR(('CDN Data'!B17),"") | I17: =IF(CPI_Downloader!G15="","",CPI_Downloader!G15) -> 9.9 | J17: =IF(CPI_Downloader!H15="","",CPI_Downloader!H15) | L17: =A17 -> 5146 | M17: =IFERROR((T17/T5-1),"") | N17: =IFERROR((U17/U16-1),"") | S17: =IF('CDN Data'!M5=0,"",IFERROR(('CDN Data'!M5),"")) | T17: =IF(CPI_Downloader!I15="","",CPI_Downloader!I15) | U17: =IF(CPI_Downloader!J15="","",CPI_Downloader!J15) | W17: =IFERROR((AVERAGE(Y6:Y17)/100),"") | X17: =IFERROR((Y17/100),"") | Y17: =IF(CPI_Downloader!K15="","",CPI_Downloader!K15) | AA17: =IFERROR((AB17/100),"") | AB17: =IF(CPI_Downloader!M15="","",CPI_Downloader!M15) | AC17: =IF(CPI_Downloader!L15="","",CPI_Downloader!L15/100) | AE17: 1 | AI17: =IFERROR((AJ17/AJ16-1),"") | AJ17: =IF(CPI_Downloader!N15="","",CPI_Downloader!N15) | AL17: =IF(CPI_Downloader!O15="","",CPI_Downloader!O15) | AN17: =IFERROR((AT17/AT5-1),"") | AO17: =IFERROR((AT17/AT16-1),"") | AT17: =IF(CPI_Downloader!P15="","",CPI_Downloader!P15) | AU17: =IFERROR((BA17/BA5-1),"") | AV17: =IFERROR((BA17/BA16-1),"") | BA17: =IF(CPI_Downloader!Q15="","",CPI_Downloader!Q15)
A18: =IF(CPI_Downloader!A16="","",CPI_Downloader!A16) -> 5174 | B18: =IFERROR((I18/I6-1),"") -> 0.010204082 | C18: =IFERROR((J18/J17-1),"") | H18: =IFERROR(('CDN Data'!B18),"") | I18: =IF(CPI_Downloader!G16="","",CPI_Downloader!G16) -> 9.9 | J18: =IF(CPI_Downloader!H16="","",CPI_Downloader!H16) | L18: =A18 -> 5174 | M18: =IFERROR((T18/T6-1),"") | N18: =IFERROR((U18/U17-1),"") | S18: =IF('CDN Data'!M6=0,"",IFERROR(('CDN Data'!M6),"")) | T18: =IF(CPI_Downloader!I16="","",CPI_Downloader!I16) | U18: =IF(CPI_Downloader!J16="","",CPI_Downloader!J16) | W18: =IFERROR((AVERAGE(Y7:Y18)/100),"") | X18: =IFERROR((Y18/100),"") | Y18: =IF(CPI_Downloader!K16="","",CPI_Downloader!K16) | AA18: =IFERROR((AB18/100),"") | AB18: =IF(CPI_Downloader!M16="","",CPI_Downloader!M16) | AC18: =IF(CPI_Downloader!L16="","",CPI_Downloader!L16/100) | AE18: 1 | AI18: =IFERROR((AJ18/AJ17-1),"") | AJ18: =IF(CPI_Downloader!N16="","",CPI_Downloader!N16) | AL18: =IF(CPI_Downloader!O16="","",CPI_Downloader!O16) | AN18: =IFERROR((AT18/AT6-1),"") | AO18: =IFERROR((AT18/AT17-1),"") | AT18: =IF(CPI_Downloader!P16="","",CPI_Downloader!P16) | AU18: =IFERROR((BA18/BA6-1),"") | AV18: =IFERROR((BA18/BA17-1),"") | BA18: =IF(CPI_Downloader!Q16="","",CPI_Downloader!Q16)
A19: =IF(CPI_Downloader!A17="","",CPI_Downloader!A17) -> 5205 | B19: =IFERROR((I19/I7-1),"") -> 0 | C19: =IFERROR((J19/J18-1),"") | H19: =IFERROR(('CDN Data'!B19),"") | I19: =IF(CPI_Downloader!G17="","",CPI_Downloader!G17) -> 9.8 | J19: =IF(CPI_Downloader!H17="","",CPI_Downloader!H17) | L19: =A19 -> 5205 | M19: =IFERROR((T19/T7-1),"") | N19: =IFERROR((U19/U18-1),"") | S19: =IF('CDN Data'!M7=0,"",IFERROR(('CDN Data'!M7),"")) | T19: =IF(CPI_Downloader!I17="","",CPI_Downloader!I17) | U19: =IF(CPI_Downloader!J17="","",CPI_Downloader!J17) | W19: =IFERROR((AVERAGE(Y8:Y19)/100),"") | X19: =IFERROR((Y19/100),"") | Y19: =IF(CPI_Downloader!K17="","",CPI_Downloader!K17) | AA19: =IFERROR((AB19/100),"") | AB19: =IF(CPI_Downloader!M17="","",CPI_Downloader!M17) | AC19: =IF(CPI_Downloader!L17="","",CPI_Downloader!L17/100) | AE19: 1 | AI19: =IFERROR((AJ19/AJ18-1),"") | AJ19: =IF(CPI_Downloader!N17="","",CPI_Downloader!N17) | AL19: =IF(CPI_Downloader!O17="","",CPI_Downloader!O17) | AN19: =IFERROR((AT19/AT7-1),"") | AO19: =IFERROR((AT19/AT18-1),"") | AT19: =IF(CPI_Downloader!P17="","",CPI_Downloader!P17) | AU19: =IFERROR((BA19/BA7-1),"") | AV19: =IFERROR((BA19/BA18-1),"") | BA19: =IF(CPI_Downloader!Q17="","",CPI_Downloader!Q17)
A20: =IF(CPI_Downloader!A18="","",CPI_Downloader!A18) -> 5235 | B20: =IFERROR((I20/I8-1),"") -> 0.020618557 | C20: =IFERROR((J20/J19-1),"") | H20: =IFERROR(('CDN Data'!B20),"") | I20: =IF(CPI_Downloader!G18="","",CPI_Downloader!G18) -> 9.9 | J20: =IF(CPI_Downloader!H18="","",CPI_Downloader!H18) | L20: =A20 -> 5235 | M20: =IFERROR((T20/T8-1),"") | N20: =IFERROR((U20/U19-1),"") | S20: =IF('CDN Data'!M8=0,"",IFERROR(('CDN Data'!M8),"")) | T20: =IF(CPI_Downloader!I18="","",CPI_Downloader!I18) | U20: =IF(CPI_Downloader!J18="","",CPI_Downloader!J18) | W20: =IFERROR((AVERAGE(Y9:Y20)/100),"") | X20: =IFERROR((Y20/100),"") | Y20: =IF(CPI_Downloader!K18="","",CPI_Downloader!K18) | AA20: =IFERROR((AB20/100),"") | AB20: =IF(CPI_Downloader!M18="","",CPI_Downloader!M18) | AC20: =IF(CPI_Downloader!L18="","",CPI_Downloader!L18/100) | AE20: 1 | AI20: =IFERROR((AJ20/AJ19-1),"") | AJ20: =IF(CPI_Downloader!N18="","",CPI_Downloader!N18) | AL20: =IF(CPI_Downloader!O18="","",CPI_Downloader!O18) | AN20: =IFERROR((AT20/AT8-1),"") | AO20: =IFERROR((AT20/AT19-1),"") | AT20: =IF(CPI_Downloader!P18="","",CPI_Downloader!P18) | AU20: =IFERROR((BA20/BA8-1),"") | AV20: =IFERROR((BA20/BA19-1),"") | BA20: =IF(CPI_Downloader!Q18="","",CPI_Downloader!Q18)
A21: =IF(CPI_Downloader!A19="","",CPI_Downloader!A19) -> 5266 | B21: =IFERROR((I21/I9-1),"") -> 0.010204082 | C21: =IFERROR((J21/J20-1),"") | H21: =IFERROR(('CDN Data'!B21),"") | I21: =IF(CPI_Downloader!G19="","",CPI_Downloader!G19) -> 9.9 | J21: =IF(CPI_Downloader!H19="","",CPI_Downloader!H19) | L21: =A21 -> 5266 | M21: =IFERROR((T21/T9-1),"") | N21: =IFERROR((U21/U20-1),"") | S21: =IF('CDN Data'!M9=0,"",IFERROR(('CDN Data'!M9),"")) | T21: =IF(CPI_Downloader!I19="","",CPI_Downloader!I19) | U21: =IF(CPI_Downloader!J19="","",CPI_Downloader!J19) | W21: =IFERROR((AVERAGE(Y10:Y21)/100),"") | X21: =IFERROR((Y21/100),"") | Y21: =IF(CPI_Downloader!K19="","",CPI_Downloader!K19) | AA21: =IFERROR((AB21/100),"") | AB21: =IF(CPI_Downloader!M19="","",CPI_Downloader!M19) | AC21: =IF(CPI_Downloader!L19="","",CPI_Downloader!L19/100) | AE21: 1 | AI21: =IFERROR((AJ21/AJ20-1),"") | AJ21: =IF(CPI_Downloader!N19="","",CPI_Downloader!N19) | AL21: =IF(CPI_Downloader!O19="","",CPI_Downloader!O19) | AN21: =IFERROR((AT21/AT9-1),"") | AO21: =IFERROR((AT21/AT20-1),"") | AT21: =IF(CPI_Downloader!P19="","",CPI_Downloader!P19) | AU21: =IFERROR((BA21/BA9-1),"") | AV21: =IFERROR((BA21/BA20-1),"") | BA21: =IF(CPI_Downloader!Q19="","",CPI_Downloader!Q19)
A22: =IF(CPI_Downloader!A20="","",CPI_Downloader!A20) -> 5296 | B22: =IFERROR((I22/I10-1),"") -> 0.01010101 | C22: =IFERROR((J22/J21-1),"") | H22: =IFERROR(('CDN Data'!B22),"") | I22: =IF(CPI_Downloader!G20="","",CPI_Downloader!G20) -> 10 | J22: =IF(CPI_Downloader!H20="","",CPI_Downloader!H20) | L22: =A22 -> 5296 | M22: =IFERROR((T22/T10-1),"") | N22: =IFERROR((U22/U21-1),"") | S22: =IF('CDN Data'!M10=0,"",IFERROR(('CDN Data'!M10),"")) | T22: =IF(CPI_Downloader!I20="","",CPI_Downloader!I20) | U22: =IF(CPI_Downloader!J20="","",CPI_Downloader!J20) | W22: =IFERROR((AVERAGE(Y11:Y22)/100),"") | X22: =IFERROR((Y22/100),"") | Y22: =IF(CPI_Downloader!K20="","",CPI_Downloader!K20) | AA22: =IFERROR((AB22/100),"") | AB22: =IF(CPI_Downloader!M20="","",CPI_Downloader!M20) | AC22: =IF(CPI_Downloader!L20="","",CPI_Downloader!L20/100) | AE22: 1 | AI22: =IFERROR((AJ22/AJ21-1),"") | AJ22: =IF(CPI_Downloader!N20="","",CPI_Downloader!N20) | AL22: =IF(CPI_Downloader!O20="","",CPI_Downloader!O20) | AN22: =IFERROR((AT22/AT10-1),"") | AO22: =IFERROR((AT22/AT21-1),"") | AT22: =IF(CPI_Downloader!P20="","",CPI_Downloader!P20) | AU22: =IFERROR((BA22/BA10-1),"") | AV22: =IFERROR((BA22/BA21-1),"") | BA22: =IF(CPI_Downloader!Q20="","",CPI_Downloader!Q20)
A23: =IF(CPI_Downloader!A21="","",CPI_Downloader!A21) -> 5327 | B23: =IFERROR((I23/I11-1),"") -> 0.03030303 | C23: =IFERROR((J23/J22-1),"") | H23: =IFERROR(('CDN Data'!B23),"") | I23: =IF(CPI_Downloader!G21="","",CPI_Downloader!G21) -> 10.2 | J23: =IF(CPI_Downloader!H21="","",CPI_Downloader!H21) | L23: =A23 -> 5327 | M23: =IFERROR((T23/T11-1),"") | N23: =IFERROR((U23/U22-1),"") | S23: =IF('CDN Data'!M11=0,"",IFERROR(('CDN Data'!M11),"")) | T23: =IF(CPI_Downloader!I21="","",CPI_Downloader!I21) | U23: =IF(CPI_Downloader!J21="","",CPI_Downloader!J21) | W23: =IFERROR((AVERAGE(Y12:Y23)/100),"") | X23: =IFERROR((Y23/100),"") | Y23: =IF(CPI_Downloader!K21="","",CPI_Downloader!K21) | AA23: =IFERROR((AB23/100),"") | AB23: =IF(CPI_Downloader!M21="","",CPI_Downloader!M21) | AC23: =IF(CPI_Downloader!L21="","",CPI_Downloader!L21/100) | AE23: 1 | AI23: =IFERROR((AJ23/AJ22-1),"") | AJ23: =IF(CPI_Downloader!N21="","",CPI_Downloader!N21) | AL23: =IF(CPI_Downloader!O21="","",CPI_Downloader!O21) | AN23: =IFERROR((AT23/AT11-1),"") | AO23: =IFERROR((AT23/AT22-1),"") | AT23: =IF(CPI_Downloader!P21="","",CPI_Downloader!P21) | AU23: =IFERROR((BA23/BA11-1),"") | AV23: =IFERROR((BA23/BA22-1),"") | BA23: =IF(CPI_Downloader!Q21="","",CPI_Downloader!Q21)
A24: =IF(CPI_Downloader!A22="","",CPI_Downloader!A22) -> 5358 | B24: =IFERROR((I24/I12-1),"") -> 0.02 | C24: =IFERROR((J24/J23-1),"") | H24: =IFERROR(('CDN Data'!B24),"") | I24: =IF(CPI_Downloader!G22="","",CPI_Downloader!G22) -> 10.2 | J24: =IF(CPI_Downloader!H22="","",CPI_Downloader!H22) | L24: =A24 -> 5358 | M24: =IFERROR((T24/T12-1),"") | N24: =IFERROR((U24/U23-1),"") | S24: =IF('CDN Data'!M12=0,"",IFERROR(('CDN Data'!M12),"")) | T24: =IF(CPI_Downloader!I22="","",CPI_Downloader!I22) | U24: =IF(CPI_Downloader!J22="","",CPI_Downloader!J22) | W24: =IFERROR((AVERAGE(Y13:Y24)/100),"") | X24: =IFERROR((Y24/100),"") | Y24: =IF(CPI_Downloader!K22="","",CPI_Downloader!K22) | AA24: =IFERROR((AB24/100),"") | AB24: =IF(CPI_Downloader!M22="","",CPI_Downloader!M22) | AC24: =IF(CPI_Downloader!L22="","",CPI_Downloader!L22/100) | AE24: 1 | AI24: =IFERROR((AJ24/AJ23-1),"") | AJ24: =IF(CPI_Downloader!N22="","",CPI_Downloader!N22) | AL24: =IF(CPI_Downloader!O22="","",CPI_Downloader!O22) | AN24: =IFERROR((AT24/AT12-1),"") | AO24: =IFERROR((AT24/AT23-1),"") | AT24: =IF(CPI_Downloader!P22="","",CPI_Downloader!P22) | AU24: =IFERROR((BA24/BA12-1),"") | AV24: =IFERROR((BA24/BA23-1),"") | BA24: =IF(CPI_Downloader!Q22="","",CPI_Downloader!Q22)
A25: =IF(CPI_Downloader!A23="","",CPI_Downloader!A23) -> 5388 | B25: =IFERROR((I25/I13-1),"") -> 0.01 | C25: =IFERROR((J25/J24-1),"") | H25: =IFERROR(('CDN Data'!B25),"") | I25: =IF(CPI_Downloader!G23="","",CPI_Downloader!G23) -> 10.1 | J25: =IF(CPI_Downloader!H23="","",CPI_Downloader!H23) | L25: =A25 -> 5388 | M25: =IFERROR((T25/T13-1),"") | N25: =IFERROR((U25/U24-1),"") | S25: =IF('CDN Data'!M13=0,"",IFERROR(('CDN Data'!M13),"")) | T25: =IF(CPI_Downloader!I23="","",CPI_Downloader!I23) | U25: =IF(CPI_Downloader!J23="","",CPI_Downloader!J23) | W25: =IFERROR((AVERAGE(Y14:Y25)/100),"") | X25: =IFERROR((Y25/100),"") | Y25: =IF(CPI_Downloader!K23="","",CPI_Downloader!K23) | AA25: =IFERROR((AB25/100),"") | AB25: =IF(CPI_Downloader!M23="","",CPI_Downloader!M23) | AC25: =IF(CPI_Downloader!L23="","",CPI_Downloader!L23/100) | AE25: 1 | AI25: =IFERROR((AJ25/AJ24-1),"") | AJ25: =IF(CPI_Downloader!N23="","",CPI_Downloader!N23) | AL25: =IF(CPI_Downloader!O23="","",CPI_Downloader!O23) | AN25: =IFERROR((AT25/AT13-1),"") | AO25: =IFERROR((AT25/AT24-1),"") | AT25: =IF(CPI_Downloader!P23="","",CPI_Downloader!P23) | AU25: =IFERROR((BA25/BA13-1),"") | AV25: =IFERROR((BA25/BA24-1),"") | BA25: =IF(CPI_Downloader!Q23="","",CPI_Downloader!Q23)
A26: =IF(CPI_Downloader!A24="","",CPI_Downloader!A24) -> 5419 | B26: =IFERROR((I26/I14-1),"") -> 0.0099009901 | C26: =IFERROR((J26/J25-1),"") | H26: =IFERROR(('CDN Data'!B26),"") | I26: =IF(CPI_Downloader!G24="","",CPI_Downloader!G24) -> 10.2 | J26: =IF(CPI_Downloader!H24="","",CPI_Downloader!H24) | L26: =A26 -> 5419 | M26: =IFERROR((T26/T14-1),"") | N26: =IFERROR((U26/U25-1),"") | S26: =IF('CDN Data'!M14=0,"",IFERROR(('CDN Data'!M14),"")) | T26: =IF(CPI_Downloader!I24="","",CPI_Downloader!I24) | U26: =IF(CPI_Downloader!J24="","",CPI_Downloader!J24) | W26: =IFERROR((AVERAGE(Y15:Y26)/100),"") | X26: =IFERROR((Y26/100),"") | Y26: =IF(CPI_Downloader!K24="","",CPI_Downloader!K24) | AA26: =IFERROR((AB26/100),"") | AB26: =IF(CPI_Downloader!M24="","",CPI_Downloader!M24) | AC26: =IF(CPI_Downloader!L24="","",CPI_Downloader!L24/100) | AE26: 1 | AI26: =IFERROR((AJ26/AJ25-1),"") | AJ26: =IF(CPI_Downloader!N24="","",CPI_Downloader!N24) | AL26: =IF(CPI_Downloader!O24="","",CPI_Downloader!O24) | AN26: =IFERROR((AT26/AT14-1),"") | AO26: =IFERROR((AT26/AT25-1),"") | AT26: =IF(CPI_Downloader!P24="","",CPI_Downloader!P24) | AU26: =IFERROR((BA26/BA14-1),"") | AV26: =IFERROR((BA26/BA25-1),"") | BA26: =IF(CPI_Downloader!Q24="","",CPI_Downloader!Q24)
A27: =IF(CPI_Downloader!A25="","",CPI_Downloader!A25) -> 5449 | B27: =IFERROR((I27/I15-1),"") -> 0.01 | C27: =IFERROR((J27/J26-1),"") | H27: =IFERROR(('CDN Data'!B27),"") | I27: =IF(CPI_Downloader!G25="","",CPI_Downloader!G25) -> 10.1 | J27: =IF(CPI_Downloader!H25="","",CPI_Downloader!H25) | L27: =A27 -> 5449 | M27: =IFERROR((T27/T15-1),"") | N27: =IFERROR((U27/U26-1),"") | S27: =IF('CDN Data'!M15=0,"",IFERROR(('CDN Data'!M15),"")) | T27: =IF(CPI_Downloader!I25="","",CPI_Downloader!I25) | U27: =IF(CPI_Downloader!J25="","",CPI_Downloader!J25) | W27: =IFERROR((AVERAGE(Y16:Y27)/100),"") | X27: =IFERROR((Y27/100),"") | Y27: =IF(CPI_Downloader!K25="","",CPI_Downloader!K25) | AA27: =IFERROR((AB27/100),"") | AB27: =IF(CPI_Downloader!M25="","",CPI_Downloader!M25) | AC27: =IF(CPI_Downloader!L25="","",CPI_Downloader!L25/100) | AE27: 0 | AI27: =IFERROR((AJ27/AJ26-1),"") | AJ27: =IF(CPI_Downloader!N25="","",CPI_Downloader!N25) | AL27: =IF(CPI_Downloader!O25="","",CPI_Downloader!O25) | AN27: =IFERROR((AT27/AT15-1),"") | AO27: =IFERROR((AT27/AT26-1),"") | AT27: =IF(CPI_Downloader!P25="","",CPI_Downloader!P25) | AU27: =IFERROR((BA27/BA15-1),"") | AV27: =IFERROR((BA27/BA26-1),"") | BA27: =IF(CPI_Downloader!Q25="","",CPI_Downloader!Q25)
A28: =IF(CPI_Downloader!A26="","",CPI_Downloader!A26) -> 5480 | B28: =IFERROR((I28/I16-1),"") -> 0.01 | C28: =IFERROR((J28/J27-1),"") | H28: =IFERROR(('CDN Data'!B28),"") -> 0.016666667 | I28: =IF(CPI_Downloader!G26="","",CPI_Downloader!G26) -> 10.1 | J28: =IF(CPI_Downloader!H26="","",CPI_Downloader!H26) | L28: =A28 -> 5480 | M28: =IFERROR((T28/T16-1),"") | N28: =IFERROR((U28/U27-1),"") | S28: =IFERROR(('CDN Data'!M16),"") | T28: =IF(CPI_Downloader!I26="","",CPI_Downloader!I26) | U28: =IF(CPI_Downloader!J26="","",CPI_Downloader!J26) | W28: =IFERROR((AVERAGE(Y17:Y28)/100),"") | X28: =IFERROR((Y28/100),"") | Y28: =IF(CPI_Downloader!K26="","",CPI_Downloader!K26) | AA28: =IFERROR((AB28/100),"") | AB28: =IF(CPI_Downloader!M26="","",CPI_Downloader!M26) | AC28: =IF(CPI_Downloader!L26="","",CPI_Downloader!L26/100) | AE28: 0 | AI28: =IFERROR((AJ28/AJ27-1),"") | AJ28: =IF(CPI_Downloader!N26="","",CPI_Downloader!N26) | AL28: =IF(CPI_Downloader!O26="","",CPI_Downloader!O26) | AN28: =IFERROR((AT28/AT16-1),"") | AO28: =IFERROR((AT28/AT27-1),"") | AT28: =IF(CPI_Downloader!P26="","",CPI_Downloader!P26) | AU28: =IFERROR((BA28/BA16-1),"") | AV28: =IFERROR((BA28/BA27-1),"") | BA28: =IF(CPI_Downloader!Q26="","",CPI_Downloader!Q26)
A29: =IF(CPI_Downloader!A27="","",CPI_Downloader!A27) -> 5511 | B29: =IFERROR((I29/I17-1),"") -> 0.01010101 | C29: =IFERROR((J29/J28-1),"") | H29: =IFERROR(('CDN Data'!B29),"") -> 0.016666667 | I29: =IF(CPI_Downloader!G27="","",CPI_Downloader!G27) -> 10 | J29: =IF(CPI_Downloader!H27="","",CPI_Downloader!H27) | L29: =A29 -> 5511 | M29: =IFERROR((T29/T17-1),"") | N29: =IFERROR((U29/U28-1),"") | S29: =IFERROR(('CDN Data'!M17),"") | T29: =IF(CPI_Downloader!I27="","",CPI_Downloader!I27) | U29: =IF(CPI_Downloader!J27="","",CPI_Downloader!J27) | W29: =IFERROR((AVERAGE(Y18:Y29)/100),"") | X29: =IFERROR((Y29/100),"") | Y29: =IF(CPI_Downloader!K27="","",CPI_Downloader!K27) | AA29: =IFERROR((AB29/100),"") | AB29: =IF(CPI_Downloader!M27="","",CPI_Downloader!M27) | AC29: =IF(CPI_Downloader!L27="","",CPI_Downloader!L27/100) | AE29: 0 | AI29: =IFERROR((AJ29/AJ28-1),"") | AJ29: =IF(CPI_Downloader!N27="","",CPI_Downloader!N27) | AL29: =IF(CPI_Downloader!O27="","",CPI_Downloader!O27) | AN29: =IFERROR((AT29/AT17-1),"") | AO29: =IFERROR((AT29/AT28-1),"") | AT29: =IF(CPI_Downloader!P27="","",CPI_Downloader!P27) | AU29: =IFERROR((BA29/BA17-1),"") | AV29: =IFERROR((BA29/BA28-1),"") | BA29: =IF(CPI_Downloader!Q27="","",CPI_Downloader!Q27)
A30: =IF(CPI_Downloader!A28="","",CPI_Downloader!A28) -> 5539 | B30: =IFERROR((I30/I18-1),"") -> 0 | C30: =IFERROR((J30/J29-1),"") | H30: =IFERROR(('CDN Data'!B30),"") -> 0.016666667 | I30: =IF(CPI_Downloader!G28="","",CPI_Downloader!G28) -> 9.9 | J30: =IF(CPI_Downloader!H28="","",CPI_Downloader!H28) | L30: =A30 -> 5539 | M30: =IFERROR((T30/T18-1),"") | N30: =IFERROR((U30/U29-1),"") | S30: =IFERROR(('CDN Data'!M18),"") | T30: =IF(CPI_Downloader!I28="","",CPI_Downloader!I28) | U30: =IF(CPI_Downloader!J28="","",CPI_Downloader!J28) | W30: =IFERROR((AVERAGE(Y19:Y30)/100),"") | X30: =IFERROR((Y30/100),"") | Y30: =IF(CPI_Downloader!K28="","",CPI_Downloader!K28) | AA30: =IFERROR((AB30/100),"") | AB30: =IF(CPI_Downloader!M28="","",CPI_Downloader!M28) | AC30: =IF(CPI_Downloader!L28="","",CPI_Downloader!L28/100) | AE30: 0 | AI30: =IFERROR((AJ30/AJ29-1),"") | AJ30: =IF(CPI_Downloader!N28="","",CPI_Downloader!N28) | AL30: =IF(CPI_Downloader!O28="","",CPI_Downloader!O28) | AN30: =IFERROR((AT30/AT18-1),"") | AO30: =IFERROR((AT30/AT29-1),"") | AT30: =IF(CPI_Downloader!P28="","",CPI_Downloader!P28) | AU30: =IFERROR((BA30/BA18-1),"") | AV30: =IFERROR((BA30/BA29-1),"") | BA30: =IF(CPI_Downloader!Q28="","",CPI_Downloader!Q28)
A31: =IF(CPI_Downloader!A29="","",CPI_Downloader!A29) -> 5570 | B31: =IFERROR((I31/I19-1),"") -> 0.020408163 | C31: =IFERROR((J31/J30-1),"") | H31: =IFERROR(('CDN Data'!B31),"") -> 0.016666667 | I31: =IF(CPI_Downloader!G29="","",CPI_Downloader!G29) -> 10 | J31: =IF(CPI_Downloader!H29="","",CPI_Downloader!H29) | L31: =A31 -> 5570 | M31: =IFERROR((T31/T19-1),"") | N31: =IFERROR((U31/U30-1),"") | S31: =IFERROR(('CDN Data'!M19),"") | T31: =IF(CPI_Downloader!I29="","",CPI_Downloader!I29) | U31: =IF(CPI_Downloader!J29="","",CPI_Downloader!J29) | W31: =IFERROR((AVERAGE(Y20:Y31)/100),"") | X31: =IFERROR((Y31/100),"") | Y31: =IF(CPI_Downloader!K29="","",CPI_Downloader!K29) | AA31: =IFERROR((AB31/100),"") | AB31: =IF(CPI_Downloader!M29="","",CPI_Downloader!M29) | AC31: =IF(CPI_Downloader!L29="","",CPI_Downloader!L29/100) | AE31: 0 | AI31: =IFERROR((AJ31/AJ30-1),"") | AJ31: =IF(CPI_Downloader!N29="","",CPI_Downloader!N29) | AL31: =IF(CPI_Downloader!O29="","",CPI_Downloader!O29) | AN31: =IFERROR((AT31/AT19-1),"") | AO31: =IFERROR((AT31/AT30-1),"") | AT31: =IF(CPI_Downloader!P29="","",CPI_Downloader!P29) | AU31: =IFERROR((BA31/BA19-1),"") | AV31: =IFERROR((BA31/BA30-1),"") | BA31: =IF(CPI_Downloader!Q29="","",CPI_Downloader!Q29)
A32: =IF(CPI_Downloader!A30="","",CPI_Downloader!A30) -> 5600 | B32: =IFERROR((I32/I20-1),"") -> 0.02020202 | C32: =IFERROR((J32/J31-1),"") | H32: =IFERROR(('CDN Data'!B32),"") -> 0.033898305 | I32: =IF(CPI_Downloader!G30="","",CPI_Downloader!G30) -> 10.1 | J32: =IF(CPI_Downloader!H30="","",CPI_Downloader!H30) | L32: =A32 -> 5600 | M32: =IFERROR((T32/T20-1),"") | N32: =IFERROR((U32/U31-1),"") | S32: =IFERROR(('CDN Data'!M20),"") | T32: =IF(CPI_Downloader!I30="","",CPI_Downloader!I30) | U32: =IF(CPI_Downloader!J30="","",CPI_Downloader!J30) | W32: =IFERROR((AVERAGE(Y21:Y32)/100),"") | X32: =IFERROR((Y32/100),"") | Y32: =IF(CPI_Downloader!K30="","",CPI_Downloader!K30) | AA32: =IFERROR((AB32/100),"") | AB32: =IF(CPI_Downloader!M30="","",CPI_Downloader!M30) | AC32: =IF(CPI_Downloader!L30="","",CPI_Downloader!L30/100) | AE32: 0 | AI32: =IFERROR((AJ32/AJ31-1),"") | AJ32: =IF(CPI_Downloader!N30="","",CPI_Downloader!N30) | AL32: =IF(CPI_Downloader!O30="","",CPI_Downloader!O30) | AN32: =IFERROR((AT32/AT20-1),"") | AO32: =IFERROR((AT32/AT31-1),"") | AT32: =IF(CPI_Downloader!P30="","",CPI_Downloader!P30) | AU32: =IFERROR((BA32/BA20-1),"") | AV32: =IFERROR((BA32/BA31-1),"") | BA32: =IF(CPI_Downloader!Q30="","",CPI_Downloader!Q30)
A33: =IF(CPI_Downloader!A31="","",CPI_Downloader!A31) -> 5631 | B33: =IFERROR((I33/I21-1),"") -> 0.02020202 | C33: =IFERROR((J33/J32-1),"") | H33: =IFERROR(('CDN Data'!B33),"") -> 0.016666667 | I33: =IF(CPI_Downloader!G31="","",CPI_Downloader!G31) -> 10.1 | J33: =IF(CPI_Downloader!H31="","",CPI_Downloader!H31) | L33: =A33 -> 5631 | M33: =IFERROR((T33/T21-1),"") | N33: =IFERROR((U33/U32-1),"") | S33: =IFERROR(('CDN Data'!M21),"") | T33: =IF(CPI_Downloader!I31="","",CPI_Downloader!I31) | U33: =IF(CPI_Downloader!J31="","",CPI_Downloader!J31) | W33: =IFERROR((AVERAGE(Y22:Y33)/100),"") | X33: =IFERROR((Y33/100),"") | Y33: =IF(CPI_Downloader!K31="","",CPI_Downloader!K31) | AA33: =IFERROR((AB33/100),"") | AB33: =IF(CPI_Downloader!M31="","",CPI_Downloader!M31) | AC33: =IF(CPI_Downloader!L31="","",CPI_Downloader!L31/100) | AE33: 0 | AI33: =IFERROR((AJ33/AJ32-1),"") | AJ33: =IF(CPI_Downloader!N31="","",CPI_Downloader!N31) | AL33: =IF(CPI_Downloader!O31="","",CPI_Downloader!O31) | AN33: =IFERROR((AT33/AT21-1),"") | AO33: =IFERROR((AT33/AT32-1),"") | AT33: =IF(CPI_Downloader!P31="","",CPI_Downloader!P31) | AU33: =IFERROR((BA33/BA21-1),"") | AV33: =IFERROR((BA33/BA32-1),"") | BA33: =IF(CPI_Downloader!Q31="","",CPI_Downloader!Q31)
A34: =IF(CPI_Downloader!A32="","",CPI_Downloader!A32) -> 5661 | B34: =IFERROR((I34/I22-1),"") -> 0.01 | C34: =IFERROR((J34/J33-1),"") | H34: =IFERROR(('CDN Data'!B34),"") -> 0.033898305 | I34: =IF(CPI_Downloader!G32="","",CPI_Downloader!G32) -> 10.1 | J34: =IF(CPI_Downloader!H32="","",CPI_Downloader!H32) | L34: =A34 -> 5661 | M34: =IFERROR((T34/T22-1),"") | N34: =IFERROR((U34/U33-1),"") | S34: =IFERROR(('CDN Data'!M22),"") | T34: =IF(CPI_Downloader!I32="","",CPI_Downloader!I32) | U34: =IF(CPI_Downloader!J32="","",CPI_Downloader!J32) | W34: =IFERROR((AVERAGE(Y23:Y34)/100),"") | X34: =IFERROR((Y34/100),"") | Y34: =IF(CPI_Downloader!K32="","",CPI_Downloader!K32) | AA34: =IFERROR((AB34/100),"") | AB34: =IF(CPI_Downloader!M32="","",CPI_Downloader!M32) | AC34: =IF(CPI_Downloader!L32="","",CPI_Downloader!L32/100) | AE34: 0 | AI34: =IFERROR((AJ34/AJ33-1),"") | AJ34: =IF(CPI_Downloader!N32="","",CPI_Downloader!N32) | AL34: =IF(CPI_Downloader!O32="","",CPI_Downloader!O32) | AN34: =IFERROR((AT34/AT22-1),"") | AO34: =IFERROR((AT34/AT33-1),"") | AT34: =IF(CPI_Downloader!P32="","",CPI_Downloader!P32) | AU34: =IFERROR((BA34/BA22-1),"") | AV34: =IFERROR((BA34/BA33-1),"") | BA34: =IF(CPI_Downloader!Q32="","",CPI_Downloader!Q32)
A35: =IF(CPI_Downloader!A33="","",CPI_Downloader!A33) -> 5692 | B35: =IFERROR((I35/I23-1),"") -> -0.0098039216 | C35: =IFERROR((J35/J34-1),"") | H35: =IFERROR(('CDN Data'!B35),"") -> 0.016666667 | I35: =IF(CPI_Downloader!G33="","",CPI_Downloader!G33) -> 10.1 | J35: =IF(CPI_Downloader!H33="","",CPI_Downloader!H33) | L35: =A35 -> 5692 | M35: =IFERROR((T35/T23-1),"") | N35: =IFERROR((U35/U34-1),"") | S35: =IFERROR(('CDN Data'!M23),"") | T35: =IF(CPI_Downloader!I33="","",CPI_Downloader!I33) | U35: =IF(CPI_Downloader!J33="","",CPI_Downloader!J33) | W35: =IFERROR((AVERAGE(Y24:Y35)/100),"") | X35: =IFERROR((Y35/100),"") | Y35: =IF(CPI_Downloader!K33="","",CPI_Downloader!K33) | AA35: =IFERROR((AB35/100),"") | AB35: =IF(CPI_Downloader!M33="","",CPI_Downloader!M33) | AC35: =IF(CPI_Downloader!L33="","",CPI_Downloader!L33/100) | AE35: 0 | AI35: =IFERROR((AJ35/AJ34-1),"") | AJ35: =IF(CPI_Downloader!N33="","",CPI_Downloader!N33) | AL35: =IF(CPI_Downloader!O33="","",CPI_Downloader!O33) | AN35: =IFERROR((AT35/AT23-1),"") | AO35: =IFERROR((AT35/AT34-1),"") | AT35: =IF(CPI_Downloader!P33="","",CPI_Downloader!P33) | AU35: =IFERROR((BA35/BA23-1),"") | AV35: =IFERROR((BA35/BA34-1),"") | BA35: =IF(CPI_Downloader!Q33="","",CPI_Downloader!Q33)
A36: =IF(CPI_Downloader!A34="","",CPI_Downloader!A34) -> 5723 | B36: =IFERROR((I36/I24-1),"") -> -0.0098039216 | C36: =IFERROR((J36/J35-1),"") | H36: =IFERROR(('CDN Data'!B36),"") -> 0.016666667 | I36: =IF(CPI_Downloader!G34="","",CPI_Downloader!G34) -> 10.1 | J36: =IF(CPI_Downloader!H34="","",CPI_Downloader!H34) | L36: =A36 -> 5723 | M36: =IFERROR((T36/T24-1),"") | N36: =IFERROR((U36/U35-1),"") | S36: =IFERROR(('CDN Data'!M24),"") | T36: =IF(CPI_Downloader!I34="","",CPI_Downloader!I34) | U36: =IF(CPI_Downloader!J34="","",CPI_Downloader!J34) | W36: =IFERROR((AVERAGE(Y25:Y36)/100),"") | X36: =IFERROR((Y36/100),"") | Y36: =IF(CPI_Downloader!K34="","",CPI_Downloader!K34) | AA36: =IFERROR((AB36/100),"") | AB36: =IF(CPI_Downloader!M34="","",CPI_Downloader!M34) | AC36: =IF(CPI_Downloader!L34="","",CPI_Downloader!L34/100) | AE36: 0 | AI36: =IFERROR((AJ36/AJ35-1),"") | AJ36: =IF(CPI_Downloader!N34="","",CPI_Downloader!N34) | AL36: =IF(CPI_Downloader!O34="","",CPI_Downloader!O34) | AN36: =IFERROR((AT36/AT24-1),"") | AO36: =IFERROR((AT36/AT35-1),"") | AT36: =IF(CPI_Downloader!P34="","",CPI_Downloader!P34) | AU36: =IFERROR((BA36/BA24-1),"") | AV36: =IFERROR((BA36/BA35-1),"") | BA36: =IF(CPI_Downloader!Q34="","",CPI_Downloader!Q34)
A37: =IF(CPI_Downloader!A35="","",CPI_Downloader!A35) -> 5753 | B37: =IFERROR((I37/I25-1),"") -> 0.0099009901 | C37: =IFERROR((J37/J36-1),"") | H37: =IFERROR(('CDN Data'!B37),"") -> 0 | I37: =IF(CPI_Downloader!G35="","",CPI_Downloader!G35) -> 10.2 | J37: =IF(CPI_Downloader!H35="","",CPI_Downloader!H35) | L37: =A37 -> 5753 | M37: =IFERROR((T37/T25-1),"") | N37: =IFERROR((U37/U36-1),"") | S37: =IFERROR(('CDN Data'!M25),"") | T37: =IF(CPI_Downloader!I35="","",CPI_Downloader!I35) | U37: =IF(CPI_Downloader!J35="","",CPI_Downloader!J35) | W37: =IFERROR((AVERAGE(Y26:Y37)/100),"") | X37: =IFERROR((Y37/100),"") | Y37: =IF(CPI_Downloader!K35="","",CPI_Downloader!K35) | AA37: =IFERROR((AB37/100),"") | AB37: =IF(CPI_Downloader!M35="","",CPI_Downloader!M35) | AC37: =IF(CPI_Downloader!L35="","",CPI_Downloader!L35/100) | AE37: 0 | AI37: =IFERROR((AJ37/AJ36-1),"") | AJ37: =IF(CPI_Downloader!N35="","",CPI_Downloader!N35) | AL37: =IF(CPI_Downloader!O35="","",CPI_Downloader!O35) | AN37: =IFERROR((AT37/AT25-1),"") | AO37: =IFERROR((AT37/AT36-1),"") | AT37: =IF(CPI_Downloader!P35="","",CPI_Downloader!P35) | AU37: =IFERROR((BA37/BA25-1),"") | AV37: =IFERROR((BA37/BA36-1),"") | BA37: =IF(CPI_Downloader!Q35="","",CPI_Downloader!Q35)
A38: =IF(CPI_Downloader!A36="","",CPI_Downloader!A36) -> 5784 | B38: =IFERROR((I38/I26-1),"") -> 0.0098039216 | C38: =IFERROR((J38/J37-1),"") | H38: =IFERROR(('CDN Data'!B38),"") -> 0.032786885 | I38: =IF(CPI_Downloader!G36="","",CPI_Downloader!G36) -> 10.3 | J38: =IF(CPI_Downloader!H36="","",CPI_Downloader!H36) | L38: =A38 -> 5784 | M38: =IFERROR((T38/T26-1),"") | N38: =IFERROR((U38/U37-1),"") | S38: =IFERROR(('CDN Data'!M26),"") | T38: =IF(CPI_Downloader!I36="","",CPI_Downloader!I36) | U38: =IF(CPI_Downloader!J36="","",CPI_Downloader!J36) | W38: =IFERROR((AVERAGE(Y27:Y38)/100),"") | X38: =IFERROR((Y38/100),"") | Y38: =IF(CPI_Downloader!K36="","",CPI_Downloader!K36) | AA38: =IFERROR((AB38/100),"") | AB38: =IF(CPI_Downloader!M36="","",CPI_Downloader!M36) | AC38: =IF(CPI_Downloader!L36="","",CPI_Downloader!L36/100) | AE38: 0 | AI38: =IFERROR((AJ38/AJ37-1),"") | AJ38: =IF(CPI_Downloader!N36="","",CPI_Downloader!N36) | AL38: =IF(CPI_Downloader!O36="","",CPI_Downloader!O36) | AN38: =IFERROR((AT38/AT26-1),"") | AO38: =IFERROR((AT38/AT37-1),"") | AT38: =IF(CPI_Downloader!P36="","",CPI_Downloader!P36) | AU38: =IFERROR((BA38/BA26-1),"") | AV38: =IFERROR((BA38/BA37-1),"") | BA38: =IF(CPI_Downloader!Q36="","",CPI_Downloader!Q36)
A39: =IF(CPI_Downloader!A37="","",CPI_Downloader!A37) -> 5814 | B39: =IFERROR((I39/I27-1),"") -> 0.01980198 | C39: =IFERROR((J39/J38-1),"") | H39: =IFERROR(('CDN Data'!B39),"") -> 0.032786885 | I39: =IF(CPI_Downloader!G37="","",CPI_Downloader!G37) -> 10.3 | J39: =IF(CPI_Downloader!H37="","",CPI_Downloader!H37) | L39: =A39 -> 5814 | M39: =IFERROR((T39/T27-1),"") | N39: =IFERROR((U39/U38-1),"") | S39: =IFERROR(('CDN Data'!M27),"") | T39: =IF(CPI_Downloader!I37="","",CPI_Downloader!I37) | U39: =IF(CPI_Downloader!J37="","",CPI_Downloader!J37) | W39: =IFERROR((AVERAGE(Y28:Y39)/100),"") | X39: =IFERROR((Y39/100),"") | Y39: =IF(CPI_Downloader!K37="","",CPI_Downloader!K37) | AA39: =IFERROR((AB39/100),"") | AB39: =IF(CPI_Downloader!M37="","",CPI_Downloader!M37) | AC39: =IF(CPI_Downloader!L37="","",CPI_Downloader!L37/100) | AE39: 0 | AI39: =IFERROR((AJ39/AJ38-1),"") | AJ39: =IF(CPI_Downloader!N37="","",CPI_Downloader!N37) | AL39: =IF(CPI_Downloader!O37="","",CPI_Downloader!O37) | AN39: =IFERROR((AT39/AT27-1),"") | AO39: =IFERROR((AT39/AT38-1),"") | AT39: =IF(CPI_Downloader!P37="","",CPI_Downloader!P37) | AU39: =IFERROR((BA39/BA27-1),"") | AV39: =IFERROR((BA39/BA38-1),"") | BA39: =IF(CPI_Downloader!Q37="","",CPI_Downloader!Q37)
A40: =IF(CPI_Downloader!A38="","",CPI_Downloader!A38) -> 5845 | B40: =IFERROR((I40/I28-1),"") -> 0.02970297 | C40: =IFERROR((J40/J39-1),"") | D40: =IFERROR(((I40/I4)^(1/3)-1),"") -> 0.020005283 | H40: =IFERROR(('CDN Data'!B40),"") -> 0.049180328 | I40: =IF(CPI_Downloader!G38="","",CPI_Downloader!G38) -> 10.4 | J40: =IF(CPI_Downloader!H38="","",CPI_Downloader!H38) | L40: =A40 -> 5845 | M40: =IFERROR((T40/T28-1),"") | N40: =IFERROR((U40/U39-1),"") | O40: =IFERROR(((T40/T4)^(1/3)-1),"") | S40: =IFERROR(('CDN Data'!M28),"") | T40: =IF(CPI_Downloader!I38="","",CPI_Downloader!I38) | U40: =IF(CPI_Downloader!J38="","",CPI_Downloader!J38) | W40: =IFERROR((AVERAGE(Y29:Y40)/100),"") | X40: =IFERROR((Y40/100),"") | Y40: =IF(CPI_Downloader!K38="","",CPI_Downloader!K38) | AA40: =IFERROR((AB40/100),"") | AB40: =IF(CPI_Downloader!M38="","",CPI_Downloader!M38) | AC40: =IF(CPI_Downloader!L38="","",CPI_Downloader!L38/100) | AE40: 0 | AI40: =IFERROR((AJ40/AJ39-1),"") | AJ40: =IF(CPI_Downloader!N38="","",CPI_Downloader!N38) | AL40: =IF(CPI_Downloader!O38="","",CPI_Downloader!O38) | AN40: =IFERROR((AT40/AT28-1),"") | AO40: =IFERROR((AT40/AT39-1),"") | AP40: =IFERROR(((AT40/AT4)^(1/3)-1),"") | AT40: =IF(CPI_Downloader!P38="","",CPI_Downloader!P38) | AU40: =IFERROR((BA40/BA28-1),"") | AV40: =IFERROR((BA40/BA39-1),"") | AW40: =IFERROR(((BA40/BA4)^(1/3)-1),"") | BA40: =IF(CPI_Downloader!Q38="","",CPI_Downloader!Q38)
...

Sheet CDN Data
A1: SA = Seasonally Adjusted | B1: Headline = All items | E1: U | F1: http://www150.statcan.gc.ca/t1/tbl1/en/tv.action?pid=1810000401 | M1: Core = Food/Energy excluded | X1: Alberta
A2: U - Unadjusted | E2: SA | F2: http://www150.statcan.gc.ca/t1/tbl1/en/tv.action?pid=1810000601
A3: Month | B3: Annual - U | C3: Monthly - SA | D3: 3yr - U | E3: 5yr - U | F3: 10yr - U | G3: 20yr - U | H3: USA Annual - U | I3: Headline CPI - U | J3: Headline CPI - SA | L3: Month | M3: Annual - U | N3: Monthly - SA | O3: 3yr - U | P3: 5yr - U | Q3: 10yr - U | R3: 20yr - U | S3: USA Annual - U | T3: Core CPI - U | U3: Core CPI - SA | W3: Month | X3: Annual Headline CPI Alberta- U | Y3: 3yr Headline CPI Alberta - U | Z3: 5yr Headline CPI Alberta - U | AA3: 10yr Headline CPI Alberta - U | AB3: 20yr Headline CPI Alberta - U | AC3: Headline CPI Alberta - U
A4: =IF(CPI_Downloader!A2="","",CPI_Downloader!A2) -> 4750 | H4: =IF('US Data'!B4=0,"",'US Data'!B4) | I4: =IF(CPI_Downloader!B2="","",CPI_Downloader!B2) | J4: =IF(CPI_Downloader!C2="","",CPI_Downloader!C2) | L4: =A4 -> 4750 | S4: =IF('US Data'!M4=0,"",IFERROR(('US Data'!M4),"")) | T4: =IF(CPI_Downloader!D2="","",CPI_Downloader!D2) | U4: =IF(CPI_Downloader!E2="","",CPI_Downloader!E2) | W4: =A4 -> 4750 | AC4: =IF(CPI_Downloader!F2="","",CPI_Downloader!F2)
A5: =IF(CPI_Downloader!A3="","",CPI_Downloader!A3) -> 4781 | C5: =IFERROR((J5/J4-1),"") | H5: =IF('US Data'!B5=0,"",'US Data'!B5) | I5: =IF(CPI_Downloader!B3="","",CPI_Downloader!B3) | J5: =IF(CPI_Downloader!C3="","",CPI_Downloader!C3) | L5: =A5 -> 4781 | N5: =IFERROR((U5/U4-1),"") | S5: =IF('US Data'!M5=0,"",IFERROR(('US Data'!M5),"")) | T5: =IF(CPI_Downloader!D3="","",CPI_Downloader!D3) | U5: =IF(CPI_Downloader!E3="","",CPI_Downloader!E3) | W5: =A5 -> 4781 | AC5: =IF(CPI_Downloader!F3="","",CPI_Downloader!F3)
A6: =IF(CPI_Downloader!A4="","",CPI_Downloader!A4) -> 4809 | C6: =IFERROR((J6/J5-1),"") | H6: =IF('US Data'!B6=0,"",'US Data'!B6) | I6: =IF(CPI_Downloader!B4="","",CPI_Downloader!B4) | J6: =IF(CPI_Downloader!C4="","",CPI_Downloader!C4) | L6: =A6 -> 4809 | N6: =IFERROR((U6/U5-1),"") | S6: =IF('US Data'!M6=0,"",IFERROR(('US Data'!M6),"")) | T6: =IF(CPI_Downloader!D4="","",CPI_Downloader!D4) | U6: =IF(CPI_Downloader!E4="","",CPI_Downloader!E4) | W6: =A6 -> 4809 | AC6: =IF(CPI_Downloader!F4="","",CPI_Downloader!F4)
A7: =IF(CPI_Downloader!A5="","",CPI_Downloader!A5) -> 4840 | C7: =IFERROR((J7/J6-1),"") | H7: =IF('US Data'!B7=0,"",'US Data'!B7) | I7: =IF(CPI_Downloader!B5="","",CPI_Downloader!B5) | J7: =IF(CPI_Downloader!C5="","",CPI_Downloader!C5) | L7: =A7 -> 4840 | N7: =IFERROR((U7/U6-1),"") | S7: =IF('US Data'!M7=0,"",IFERROR(('US Data'!M7),"")) | T7: =IF(CPI_Downloader!D5="","",CPI_Downloader!D5) | U7: =IF(CPI_Downloader!E5="","",CPI_Downloader!E5) | W7: =A7 -> 4840 | AC7: =IF(CPI_Downloader!F5="","",CPI_Downloader!F5)
A8: =IF(CPI_Downloader!A6="","",CPI_Downloader!A6) -> 4870 | C8: =IFERROR((J8/J7-1),"") | H8: =IF('US Data'!B8=0,"",'US Data'!B8) | I8: =IF(CPI_Downloader!B6="","",CPI_Downloader!B6) | J8: =IF(CPI_Downloader!C6="","",CPI_Downloader!C6) | L8: =A8 -> 4870 | N8: =IFERROR((U8/U7-1),"") | S8: =IF('US Data'!M8=0,"",IFERROR(('US Data'!M8),"")) | T8: =IF(CPI_Downloader!D6="","",CPI_Downloader!D6) | U8: =IF(CPI_Downloader!E6="","",CPI_Downloader!E6) | W8: =A8 -> 4870 | AC8: =IF(CPI_Downloader!F6="","",CPI_Downloader!F6)
A9: =IF(CPI_Downloader!A7="","",CPI_Downloader!A7) -> 4901 | C9: =IFERROR((J9/J8-1),"") | H9: =IF('US Data'!B9=0,"",'US Data'!B9) | I9: =IF(CPI_Downloader!B7="","",CPI_Downloader!B7) | J9: =IF(CPI_Downloader!C7="","",CPI_Downloader!C7) | L9: =A9 -> 4901 | N9: =IFERROR((U9/U8-1),"") | S9: =IF('US Data'!M9=0,"",IFERROR(('US Data'!M9),"")) | T9: =IF(CPI_Downloader!D7="","",CPI_Downloader!D7) | U9: =IF(CPI_Downloader!E7="","",CPI_Downloader!E7) | W9: =A9 -> 4901 | AC9: =IF(CPI_Downloader!F7="","",CPI_Downloader!F7)
A10: =IF(CPI_Downloader!A8="","",CPI_Downloader!A8) -> 4931 | C10: =IFERROR((J10/J9-1),"") | H10: =IF('US Data'!B10=0,"",'US Data'!B10) | I10: =IF(CPI_Downloader!B8="","",CPI_Downloader!B8) | J10: =IF(CPI_Downloader!C8="","",CPI_Downloader!C8) | L10: =A10 -> 4931 | N10: =IFERROR((U10/U9-1),"") | S10: =IF('US Data'!M10=0,"",IFERROR(('US Data'!M10),"")) | T10: =IF(CPI_Downloader!D8="","",CPI_Downloader!D8) | U10: =IF(CPI_Downloader!E8="","",CPI_Downloader!E8) | W10: =A10 -> 4931 | AC10: =IF(CPI_Downloader!F8="","",CPI_Downloader!F8)
A11: =IF(CPI_Downloader!A9="","",CPI_Downloader!A9) -> 4962 | C11: =IFERROR((J11/J10-1),"") | H11: =IF('US Data'!B11=0,"",'US Data'!B11) | I11: =IF(CPI_Downloader!B9="","",CPI_Downloader!B9) | J11: =IF(CPI_Downloader!C9="","",CPI_Downloader!C9) | L11: =A11 -> 4962 | N11: =IFERROR((U11/U10-1),"") | S11: =IF('US Data'!M11=0,"",IFERROR(('US Data'!M11),"")) | T11: =IF(CPI_Downloader!D9="","",CPI_Downloader!D9) | U11: =IF(CPI_Downloader!E9="","",CPI_Downloader!E9) | W11: =A11 -> 4962 | AC11: =IF(CPI_Downloader!F9="","",CPI_Downloader!F9)
A12: =IF(CPI_Downloader!A10="","",CPI_Downloader!A10) -> 4993 | C12: =IFERROR((J12/J11-1),"") | H12: =IF('US Data'!B12=0,"",'US Data'!B12) | I12: =IF(CPI_Downloader!B10="","",CPI_Downloader!B10) | J12: =IF(CPI_Downloader!C10="","",CPI_Downloader!C10) | L12: =A12 -> 4993 | N12: =IFERROR((U12/U11-1),"") | S12: =IF('US Data'!M12=0,"",IFERROR(('US Data'!M12),"")) | T12: =IF(CPI_Downloader!D10="","",CPI_Downloader!D10) | U12: =IF(CPI_Downloader!E10="","",CPI_Downloader!E10) | W12: =A12 -> 4993 | AC12: =IF(CPI_Downloader!F10="","",CPI_Downloader!F10)
A13: =IF(CPI_Downloader!A11="","",CPI_Downloader!A11) -> 5023 | C13: =IFERROR((J13/J12-1),"") | H13: =IF('US Data'!B13=0,"",'US Data'!B13) | I13: =IF(CPI_Downloader!B11="","",CPI_Downloader!B11) | J13: =IF(CPI_Downloader!C11="","",CPI_Downloader!C11) | L13: =A13 -> 5023 | N13: =IFERROR((U13/U12-1),"") | S13: =IF('US Data'!M13=0,"",IFERROR(('US Data'!M13),"")) | T13: =IF(CPI_Downloader!D11="","",CPI_Downloader!D11) | U13: =IF(CPI_Downloader!E11="","",CPI_Downloader!E11) | W13: =A13 -> 5023 | AC13: =IF(CPI_Downloader!F11="","",CPI_Downloader!F11)
A14: =IF(CPI_Downloader!A12="","",CPI_Downloader!A12) -> 5054 | C14: =IFERROR((J14/J13-1),"") | H14: =IF('US Data'!B14=0,"",'US Data'!B14) | I14: =IF(CPI_Downloader!B12="","",CPI_Downloader!B12) | J14: =IF(CPI_Downloader!C12="","",CPI_Downloader!C12) | L14: =A14 -> 5054 | N14: =IFERROR((U14/U13-1),"") | S14: =IF('US Data'!M14=0,"",IFERROR(('US Data'!M14),"")) | T14: =IF(CPI_Downloader!D12="","",CPI_Downloader!D12) | U14: =IF(CPI_Downloader!E12="","",CPI_Downloader!E12) | W14: =A14 -> 5054 | AC14: =IF(CPI_Downloader!F12="","",CPI_Downloader!F12)
A15: =IF(CPI_Downloader!A13="","",CPI_Downloader!A13) -> 5084 | C15: =IFERROR((J15/J14-1),"") | H15: =IF('US Data'!B15=0,"",'US Data'!B15) | I15: =IF(CPI_Downloader!B13="","",CPI_Downloader!B13) | J15: =IF(CPI_Downloader!C13="","",CPI_Downloader!C13) | L15: =A15 -> 5084 | N15: =IFERROR((U15/U14-1),"") | S15: =IF('US Data'!M15=0,"",IFERROR(('US Data'!M15),"")) | T15: =IF(CPI_Downloader!D13="","",CPI_Downloader!D13) | U15: =IF(CPI_Downloader!E13="","",CPI_Downloader!E13) | W15: =A15 -> 5084 | AC15: =IF(CPI_Downloader!F13="","",CPI_Downloader!F13)
A16: =IF(CPI_Downloader!A14="","",CPI_Downloader!A14) -> 5115 | B16: =IFERROR((I16/I4-1),"") | C16: =IFERROR((J16/J15-1),"") | H16: ='US Data'!B16 -> 0.020408163 | I16: =IF(CPI_Downloader!B14="","",CPI_Downloader!B14) -> 6 | J16: =IF(CPI_Downloader!C14="","",CPI_Downloader!C14) | L16: =A16 -> 5115 | M16: =IFERROR((T16/T4-1),"") | N16: =IFERROR((U16/U15-1),"") | S16: =IFERROR(('US Data'!M16),"") | T16: =IF(CPI_Downloader!D14="","",CPI_Downloader!D14) | U16: =IF(CPI_Downloader!E14="","",CPI_Downloader!E14) | W16: =A16 -> 5115 | X16: =IFERROR((AC16/AC4-1),"") | AC16: =IF(CPI_Downloader!F14="","",CPI_Downloader!F14)
A17: =IF(CPI_Downloader!A15="","",CPI_Downloader!A15) -> 5146 | B17: =IFERROR((I17/I5-1),"") | C17: =IFERROR((J17/J16-1),"") | H17: ='US Data'!B17 -> 0.010204082 | I17: =IF(CPI_Downloader!B15="","",CPI_Downloader!B15) -> 6 | J17: =IF(CPI_Downloader!C15="","",CPI_Downloader!C15) | L17: =A17 -> 5146 | M17: =IFERROR((T17/T5-1),"") | N17: =IFERROR((U17/U16-1),"") | S17: =IFERROR(('US Data'!M17),"") | T17: =IF(CPI_Downloader!D15="","",CPI_Downloader!D15) | U17: =IF(CPI_Downloader!E15="","",CPI_Downloader!E15) | W17: =A17 -> 5146 | X17: =IFERROR((AC17/AC5-1),"") | AC17: =IF(CPI_Downloader!F15="","",CPI_Downloader!F15)
A18: =IF(CPI_Downloader!A16="","",CPI_Downloader!A16) -> 5174 | B18: =IFERROR((I18/I6-1),"") | C18: =IFERROR((J18/J17-1),"") | H18: ='US Data'!B18 -> 0.010204082 | I18: =IF(CPI_Downloader!B16="","",CPI_Downloader!B16) -> 6 | J18: =IF(CPI_Downloader!C16="","",CPI_Downloader!C16) | L18: =A18 -> 5174 | M18: =IFERROR((T18/T6-1),"") | N18: =IFERROR((U18/U17-1),"") | S18: =IFERROR(('US Data'!M18),"") | T18: =IF(CPI_Downloader!D16="","",CPI_Downloader!D16) | U18: =IF(CPI_Downloader!E16="","",CPI_Downloader!E16) | W18: =A18 -> 5174 | X18: =IFERROR((AC18/AC6-1),"") | AC18: =IF(CPI_Downloader!F16="","",CPI_Downloader!F16)
A19: =IF(CPI_Downloader!A17="","",CPI_Downloader!A17) -> 5205 | B19: =IFERROR((I19/I7-1),"") | C19: =IFERROR((J19/J18-1),"") | H19: ='US Data'!B19 -> 0 | I19: =IF(CPI_Downloader!B17="","",CPI_Downloader!B17) -> 6 | J19: =IF(CPI_Downloader!C17="","",CPI_Downloader!C17) | L19: =A19 -> 5205 | M19: =IFERROR((T19/T7-1),"") | N19: =IFERROR((U19/U18-1),"") | S19: =IFERROR(('US Data'!M19),"") | T19: =IF(CPI_Downloader!D17="","",CPI_Downloader!D17) | U19: =IF(CPI_Downloader!E17="","",CPI_Downloader!E17) | W19: =A19 -> 5205 | X19: =IFERROR((AC19/AC7-1),"") | AC19: =IF(CPI_Downloader!F17="","",CPI_Downloader!F17)
A20: =IF(CPI_Downloader!A18="","",CPI_Downloader!A18) -> 5235 | B20: =IFERROR((I20/I8-1),"") | C20: =IFERROR((J20/J19-1),"") | H20: ='US Data'!B20 -> 0.020618557 | I20: =IF(CPI_Downloader!B18="","",CPI_Downloader!B18) -> 5.9 | J20: =IF(CPI_Downloader!C18="","",CPI_Downloader!C18) | L20: =A20 -> 5235 | M20: =IFERROR((T20/T8-1),"") | N20: =IFERROR((U20/U19-1),"") | S20: =IFERROR(('US Data'!M20),"") | T20: =IF(CPI_Downloader!D18="","",CPI_Downloader!D18) | U20: =IF(CPI_Downloader!E18="","",CPI_Downloader!E18) | W20: =A20 -> 5235 | X20: =IFERROR((AC20/AC8-1),"") | AC20: =IF(CPI_Downloader!F18="","",CPI_Downloader!F18)
A21: =IF(CPI_Downloader!A19="","",CPI_Downloader!A19) -> 5266 | B21: =IFERROR((I21/I9-1),"") | C21: =IFERROR((J21/J20-1),"") | H21: ='US Data'!B21 -> 0.010204082 | I21: =IF(CPI_Downloader!B19="","",CPI_Downloader!B19) -> 6 | J21: =IF(CPI_Downloader!C19="","",CPI_Downloader!C19) | L21: =A21 -> 5266 | M21: =IFERROR((T21/T9-1),"") | N21: =IFERROR((U21/U20-1),"") | S21: =IFERROR(('US Data'!M21),"") | T21: =IF(CPI_Downloader!D19="","",CPI_Downloader!D19) | U21: =IF(CPI_Downloader!E19="","",CPI_Downloader!E19) | W21: =A21 -> 5266 | X21: =IFERROR((AC21/AC9-1),"") | AC21: =IF(CPI_Downloader!F19="","",CPI_Downloader!F19)
A22: =IF(CPI_Downloader!A20="","",CPI_Downloader!A20) -> 5296 | B22: =IFERROR((I22/I10-1),"") | C22: =IFERROR((J22/J21-1),"") | H22: ='US Data'!B22 -> 0.01010101 | I22: =IF(CPI_Downloader!B20="","",CPI_Downloader!B20) -> 5.9 | J22: =IF(CPI_Downloader!C20="","",CPI_Downloader!C20) | L22: =A22 -> 5296 | M22: =IFERROR((T22/T10-1),"") | N22: =IFERROR((U22/U21-1),"") | S22: =IFERROR(('US Data'!M22),"") | T22: =IF(CPI_Downloader!D20="","",CPI_Downloader!D20) | U22: =IF(CPI_Downloader!E20="","",CPI_Downloader!E20) | W22: =A22 -> 5296 | X22: =IFERROR((AC22/AC10-1),"") | AC22: =IF(CPI_Downloader!F20="","",CPI_Downloader!F20)
A23: =IF(CPI_Downloader!A21="","",CPI_Downloader!A21) -> 5327 | B23: =IFERROR((I23/I11-1),"") | C23: =IFERROR((J23/J22-1),"") | H23: ='US Data'!B23 -> 0.03030303 | I23: =IF(CPI_Downloader!B21="","",CPI_Downloader!B21) -> 6 | J23: =IF(CPI_Downloader!C21="","",CPI_Downloader!C21) | L23: =A23 -> 5327 | M23: =IFERROR((T23/T11-1),"") | N23: =IFERROR((U23/U22-1),"") | S23: =IFERROR(('US Data'!M23),"") | T23: =IF(CPI_Downloader!D21="","",CPI_Downloader!D21) | U23: =IF(CPI_Downloader!E21="","",CPI_Downloader!E21) | W23: =A23 -> 5327 | X23: =IFERROR((AC23/AC11-1),"") | AC23: =IF(CPI_Downloader!F21="","",CPI_Downloader!F21)
