Workbook

Sheet CPI_Downloader
A1: Date | B1: Headline CPI - Unadjusted CDN | C1: Headline CPI - Seasonally Adjusted CDN | D1: Core CPI - Unadjusted CDN | E1: Core CPI - Seasonally Adjusted CDN | F1: Alberta CPI - Unadjusted CDN | G1: Headline CPI - Unadjusted US | H1: Headline CPI - Seasonally Adjusted US | I1: Core CPI - Unadjusted US | J1: Core CPI - Seasonally Adjusted US | K1: Unemployment Rate - Seasonally Adjusted US | L1: Monthly Effective Fed Fund Rate US | M1: Monthly Fed Fund Rate - EOP US | N1: SP by month US | O1: 10yr vs 2yr US | P1: 10-Year Treasury Yield - Monthly Average US | Q1: 2-Year Treasury Yield - Monthly Average US | R1: PCE - Seasonally Adjusted US | S1: Core PCE - Seasonally Adjusted US
A2: 4750 | G2: 9.8
A3: 4781 | G3: 9.8
A4: 4809 | G4: 9.8
A5: 4840 | G5: 9.8
A6: 4870 | G6: 9.7
A7: 4901 | G7: 9.8
A8: 4931 | G8: 9.9
A9: 4962 | G9: 9.9
A10: 4993 | G10: 10
A11: 5023 | G11: 10
A12: 5054 | G12: 10.1
A13: 5084 | G13: 10
A14: 5115 | B14: 6 | G14: 10
A15: 5146 | B15: 6 | G15: 9.9
A16: 5174 | B16: 6 | G16: 9.9
A17: 5205 | B17: 6 | G17: 9.8
A18: 5235 | B18: 5.9 | G18: 9.9
A19: 5266 | B19: 6 | G19: 9.9
A20: 5296 | B20: 5.9 | G20: 10
A21: 5327 | B21: 6 | G21: 10.2
A22: 5358 | B22: 6 | G22: 10.2
A23: 5388 | B23: 6.1 | G23: 10.1
A24: 5419 | B24: 6.1 | G24: 10.2
A25: 5449 | B25: 6.1 | G25: 10.1
... A409: 17137 | B409: 9.7 | G409: 21.5
A410: 17168 | B410: 9.7 | G410: 21.5 | H410: 21.48
A411: 17199 | B411: 9.7 | G411: 21.5 | H411: 21.62
A412: 17227 | B412: 9.8 | G412: 21.9 | H412: 22
A413: 17258 | B413: 9.9 | G413: 21.9 | H413: 22
A414: 17288 | B414: 10.1 | G414: 21.9 | H414: 21.95
A415: 17319 | B415: 10.2 | G415: 22 | H415: 22.08
A416: 17349 | B416: 10.3 | G416: 22.2 | H416: 22.23
A417: 17380 | B417: 10.3 | G417: 22.5 | H417: 22.4
A418: 17411 | B418: 10.6 | G418: 23 | H418: 22.84
A419: 17441 | B419: 10.8 | G419: 23 | H419: 22.91
A420: 17472 | B420: 10.9 | G420: 23.1 | H420: 23.06
A421: 17502 | B421: 11.1 | G421: 23.4 | H421: 23.41
A422: 17533 | B422: 11.2 | G422: 23.7 | H422: 23.68 | K422: 3.4
A423: 17564 | B423: 11.4 | G423: 23.5 | H423: 23.67 | K423: 3.8
...

Sheet US Data
A1: SA = Seasonally Adjusted | B1: Headline = All Items | J1: https://fred.stlouisfed.org/tags/series?t=cbsa%3Bcpi&rt=cbsa&ob=pv&od=desc | L1: Core = Food/Energy excluded | T1: https://fred.stlouisfed.org/series/CPILFESL | X1: NOTE: MAY NOT MATCH AS SA | Z1: Effective Fed Funds Rate | AA1: https://fred.stlouisfed.org/series/FEDFUNDS | AD1: 0% = No recession | AF1: National Bureau of Economic Research | AG1: https://en.wikipedia.org/wiki/List_of_recessions_in_the_United_States | AM1: Headline = All Items | AS1: https://fred.stlouisfed.org/series/PCEPI | AU1: Core = Food/ Energy excluded | BA1: https://fred.stlouisfed.org/series/PCEPILFE
A2: U - Unadjusted | C2: https://www.bls.gov/cpi/seasonal-adjustment/home.htm | J2: https://fred.stlouisfed.org/series/CPIAUCNS | T2: https://fred.stlouisfed.org/series/CPILFENS | X2: https://fred.stlouisfed.org/series/UNRATE | Z2: EOP = End of Period | AA2: https://fred.stlouisfed.org/series/DFF | AD2: 100% = recession | AI2: https://fred.stlouisfed.org/series/T10Y2Y
A3: Extra Notes/Details | B3: Note: Each year, for the January CPI release, the seasonal adjustment factors are recalculated for the previous 5 years. | J3: https://fred.stlouisfed.org/series/CPIAUCSL | AD3: https://www.nber.org/research/data/us-business-cycle-expansions-and-contractions | AF3: https://fred.stlouisfed.org/series/SP500#0
A4: Month | B4: Annual Headline CPI - U | C4: Monthly Headline CPI - SA | D4: 3yr Headline CPI - U | E4: 5yr Headline CPI - U | F4: 10yr Headline CPI - U | G4: 20yr Headline CPI - U | H4: CDN Annual Headline CPI - U | I4: US Headline CPI - U - DATA | J4: US Headline CPI - SA - DATA | L4: Annual Core CPI - U | M4: Monthly Core CPI - SA | N4: 3yr Core CPI - U | O4: 5yr Core CPI - U | P4: 10yr Core CPI - U | Q4: 20yr Core CPI - U | R4: CDN Annual Core CPI - U | S4: Core CPI - U - DATA | T4: Core CPI - SA - DATA | V4: 12M Average Unemployment - SA | W4: Monthly Unemployment - SA | X4: Unemployment Rate SA - DATA | Z4: Monthly Fed Fund Rate EOP | AA4: Monthly Fed Fund Rate - EOP - DATA | AB4: Monthly Fed Fund Rate Month AVG - DATA | AD4: US Recessions (per NBER) | AF4: S&P % By month | AG4: S&P 500 EOM | AI4: 10yr vs 2yr EOP | AJ4: 10yr Month AVG | AK4: 2yr Month AVG | AM4: Annual Headline PCE | AN4: Monthly Headline PCE | AO4: 3yr Headline PCE | AP4: 5yr Headline PCE | AQ4: 10yr Headline PCE | AR4: 20yr Headline PCE | AS4: Headline PCE SA | AU4: Annual Core PCE | AV4: Monthly Core PCE | AW4: 3yr Core PCE | AX4: 5yr Core PCE | AY4: 10yr Core PCE | AZ4: 20yr Core PCE | BA4: Core PCE SA
A5: {=_xlfn.LET(_xlpm.Dates,CPI_Downloader!$A$2:$A$5000,_xlpm.Data,CPI_Downloader!$B$2:$S$5000,_xlfn._xlws.FILTER(_xlpm.Dates,_xlfn.BYROW(_xlpm.Data,_xlfn.LAMBDA(_xlpm.r,COUNT(_xlpm.r)>0)),""))} -> 4750 | B5: {=_xlfn.MAP(_xlfn.ANCHORARRAY($A$5),_xlfn.LAMBDA(_xlpm.d,_xlfn.LET(_xlpm.v,_xlfn.XLOOKUP(_xlpm.d,CPI_Downloader!$A$2:$A$5000,CPI_Downloader!$G$2:$G$5000,""),_xlpm.p,_xlfn.XLOOKUP(EDATE(_xlpm.d,-12),CPI_Downloader!$A$2:$A$5000,CPI_Downloader!$G$2:$G$5000,""),IF(OR(_xlpm.v="",_xlpm.p=""),"",IFERROR(_xlpm.v/_xlpm.p-1,"")))))} | C5: {=_xlfn.MAP(_xlfn.ANCHORARRAY($A$5),_xlfn.LAMBDA(_xlpm.d,_xlfn.LET(_xlpm.v,_xlfn.XLOOKUP(_xlpm.d,CPI_Downloader!$A$2:$A$5000,CPI_Downloader!$H$2:$H$5000,""),_xlpm.p,_xlfn.XLOOKUP(EDATE(_xlpm.d,-1),CPI_Downloader!$A$2:$A$5000,CPI_Downloader!$H$2:$H$5000,""),IF(OR(_xlpm.v="",_xlpm.p=""),"",IFERROR(_xlpm.v/_xlpm.p-1,"")))))} | D5: {=_xlfn.MAP(_xlfn.ANCHORARRAY($A$5),_xlfn.LAMBDA(_xlpm.d,_xlfn.LET(_xlpm.v,_xlfn.XLOOKUP(_xlpm.d,CPI_Downloader!$A$2:$A$5000,CPI_Downloader!$G$2:$G$5000,""),_xlpm.p,_xlfn.XLOOKUP(EDATE(_xlpm.d,-36),CPI_Downloader!$A$2:$A$5000,CPI_Downloader!$G$2:$G$5000,""),IF(OR(_xlpm.v="",_xlpm.p=""),"",IFERROR((_xlpm.v/_xlpm.p)^(1/3)-1,"")))))} | E5: {=_xlfn.MAP(_xlfn.ANCHORARRAY($A$5),_xlfn.LAMBDA(_xlpm.d,_xlfn.LET(_xlpm.v,_xlfn.XLOOKUP(_xlpm.d,CPI_Downloader!$A$2:$A$5000,CPI_Downloader!$G$2:$G$5000,""),_xlpm.p,_xlfn.XLOOKUP(EDATE(_xlpm.d,-60),CPI_Downloader!$A$2:$A$5000,CPI_Downloader!$G$2:$G$5000,""),IF(OR(_xlpm.v="",_xlpm.p=""),"",IFERROR((_xlpm.v/_xlpm.p)^(1/5)-1,"")))))} | F5: {=_xlfn.MAP(_xlfn.ANCHORARRAY($A$5),_xlfn.LAMBDA(_xlpm.d,_xlfn.LET(_xlpm.v,_xlfn.XLOOKUP(_xlpm.d,CPI_Downloader!$A$2:$A$5000,CPI_Downloader!$G$2:$G$5000,""),_xlpm.p,_xlfn.XLOOKUP(EDATE(_xlpm.d,-120),CPI_Downloader!$A$2:$A$5000,CPI_Downloader!$G$2:$G$5000,""),IF(OR(_xlpm.v="",_xlpm.p=""),"",IFERROR((_xlpm.v/_xlpm.p)^(1/10)-1,"")))))} | G5: {=_xlfn.MAP(_xlfn.ANCHORARRAY($A$5),_xlfn.LAMBDA(_xlpm.d,_xlfn.LET(_xlpm.v,_xlfn.XLOOKUP(_xlpm.d,CPI_Downloader!$A$2:$A$5000,CPI_Downloader!$G$2:$G$5000,""),_xlpm.p,IFERROR(_xlfn.XLOOKUP(EDATE(_xlpm.d,-240),CPI_Downloader!$A$2:$A$5000,CPI_Downloader!$G$2:$G$5000,""),""),IF(OR(_xlpm.v="",_xlpm.p=""),"",IFERROR((_xlpm.v/_xlpm.p)^(1/20)-1,"")))))} | H5: {=_xlfn.MAP(_xlfn.ANCHORARRAY($A$5),_xlfn.LAMBDA(_xlpm.d,_xlfn.LET(_xlpm.v,_xlfn.XLOOKUP(_xlpm.d,CPI_Downloader!$A$2:$A$5000,CPI_Downloader!$B$2:$B$5000,""),_xlpm.p,_xlfn.XLOOKUP(EDATE(_xlpm.d,-12),CPI_Downloader!$A$2:$A$5000,CPI_Downloader!$B$2:$B$5000,""),IF(OR(_xlpm.v="",_xlpm.p=""),"",IFERROR(_xlpm.v/_xlpm.p-1,"")))))} | I5: {=_xlfn.LET(_xlpm.v,_xlfn.XLOOKUP(_xlfn.ANCHORARRAY($A$5),CPI_Downloader!$A$2:$A$5000,CPI_Downloader!$G$2:$G$5000,""),IF(_xlpm.v="","",_xlpm.v))} -> 9.8 | J5: {=_xlfn.LET(_xlpm.v,_xlfn.XLOOKUP(_xlfn.ANCHORARRAY($A$5),CPI_Downloader!$A$2:$A$5000,CPI_Downloader!$H$2:$H$5000,""),IF(_xlpm.v="","",_xlpm.v))} | L5: {=_xlfn.MAP(_xlfn.ANCHORARRAY($A$5),_xlfn.LAMBDA(_xlpm.d,_xlfn.LET(_xlpm.v,_xlfn.XLOOKUP(_xlpm.d,CPI_Downloader!$A$2:$A$5000,CPI_Downloader!$I$2:$I$5000,""),_xlpm.p,_xlfn.XLOOKUP(EDATE(_xlpm.d,-12),CPI_Downloader!$A$2:$A$5000,CPI_Downloader!$I$2:$I$5000,""),IF(OR(_xlpm.v="",_xlpm.p=""),"",IFERROR(_xlpm.v/_xlpm.p-1,"")))))} | M5: {=_xlfn.MAP(_xlfn.ANCHORARRAY($A$5),_xlfn.LAMBDA(_xlpm.d,_xlfn.LET(_xlpm.v,_xlfn.XLOOKUP(_xlpm.d,CPI_Downloader!$A$2:$A$5000,CPI_Downloader!$J$2:$J$5000,""),_xlpm.p,_xlfn.XLOOKUP(EDATE(_xlpm.d,-1),CPI_Downloader!$A$2:$A$5000,CPI_Downloader!$J$2:$J$5000,""),IF(OR(_xlpm.v="",_xlpm.p=""),"",IFERROR(_xlpm.v/_xlpm.p-1,"")))))} | N5: {=_xlfn.MAP(_xlfn.ANCHORARRAY($A$5),_xlfn.LAMBDA(_xlpm.d,_xlfn.LET(_xlpm.v,_xlfn.XLOOKUP(_xlpm.d,CPI_Downloader!$A$2:$A$5000,CPI_Downloader!$I$2:$I$5000,""),_xlpm.p,_xlfn.XLOOKUP(EDATE(_xlpm.d,-36),CPI_Downloader!$A$2:$A$5000,CPI_Downloader!$I$2:$I$5000,""),IF(OR(_xlpm.v="",_xlpm.p=""),"",IFERROR((_xlpm.v/_xlpm.p)^(1/3)-1,"")))))} | O5: {=_xlfn.MAP(_xlfn.ANCHORARRAY($A$5),_xlfn.LAMBDA(_xlpm.d,_xlfn.LET(_xlpm.v,_xlfn.XLOOKUP(_xlpm.d,CPI_Downloader!$A$2:$A$5000,CPI_Downloader!$I$2:$I$5000,""),_xlpm.p,_xlfn.XLOOKUP(EDATE(_xlpm.d,-60),CPI_Downloader!$A$2:$A$5000,CPI_Downloader!$I$2:$I$5000,""),IF(OR(_xlpm.v="",_xlpm.p=""),"",IFERROR((_xlpm.v/_xlpm.p)^(1/5)-1,"")))))} | P5: {=_xlfn.MAP(_xlfn.ANCHORARRAY($A$5),_xlfn.LAMBDA(_xlpm.d,_xlfn.LET(_xlpm.v,_xlfn.XLOOKUP(_xlpm.d,CPI_Downloader!$A$2:$A$5000,CPI_Downloader!$I$2:$I$5000,""),_xlpm.p,_xlfn.XLOOKUP(EDATE(_xlpm.d,-120),CPI_Downloader!$A$2:$A$5000,CPI_Downloader!$I$2:$I$5000,""),IF(OR(_xlpm.v="",_xlpm.p=""),"",IFERROR((_xlpm.v/_xlpm.p)^(1/10)-1,"")))))} | Q5: {=_xlfn.MAP(_xlfn.ANCHORARRAY($A$5),_xlfn.LAMBDA(_xlpm.d,_xlfn.LET(_xlpm.v,_xlfn.XLOOKUP(_xlpm.d,CPI_Downloader!$A$2:$A$5000,CPI_Downloader!$I$2:$I$5000,""),_xlpm.p,IFERROR(_xlfn.XLOOKUP(EDATE(_xlpm.d,-240),CPI_Downloader!$A$2:$A$5000,CPI_Downloader!$I$2:$I$5000,""),""),IF(OR(_xlpm.v="",_xlpm.p=""),"",IFERROR((_xlpm.v/_xlpm.p)^(1/20)-1,"")))))} | R5: {=_xlfn.MAP(_xlfn.ANCHORARRAY($A$5),_xlfn.LAMBDA(_xlpm.d,_xlfn.LET(_xlpm.v,_xlfn.XLOOKUP(_xlpm.d,CPI_Downloader!$A$2:$A$5000,CPI_Downloader!$D$2:$D$5000,""),_xlpm.p,_xlfn.XLOOKUP(EDATE(_xlpm.d,-12),CPI_Downloader!$A$2:$A$5000,CPI_Downloader!$D$2:$D$5000,""),IF(OR(_xlpm.v="",_xlpm.p=""),"",IFERROR(_xlpm.v/_xlpm.p-1,"")))))} | S5: {=_xlfn.LET(_xlpm.v,_xlfn.XLOOKUP(_xlfn.ANCHORARRAY($A$5),CPI_Downloader!$A$2:$A$5000,CPI_Downloader!$I$2:$I$5000,""),IF(_xlpm.v="","",_xlpm.v))} | T5: {=_xlfn.LET(_xlpm.v,_xlfn.XLOOKUP(_xlfn.ANCHORARRAY($A$5),CPI_Downloader!$A$2:$A$5000,CPI_Downloader!$J$2:$J$5000,""),IF(_xlpm.v="","",_xlpm.v))} | V5: {=_xlfn.MAP(_xlfn.ANCHORARRAY($A$5),_xlfn.LAMBDA(_xlpm.d,_xlfn.LET(_xlpm.v,_xlfn._xlws.FILTER(CPI_Downloader!$K$2:$K$5000,(CPI_Downloader!$A$2:$A$5000>=EDATE(_xlpm.d,-11))*(CPI_Downloader!$A$2:$A$5000<=_xlpm.d)*(CPI_Downloader!$K$2:$K$5000<>""),""),IF(COUNT(_xlpm.v)=12,AVERAGE(_xlpm.v)/100,""))))} | W5: {=_xlfn.LET(_xlpm.v,_xlfn.XLOOKUP(_xlfn.ANCHORARRAY($A$5),CPI_Downloader!$A$2:$A$5000,CPI_Downloader!$K$2:$K$5000,""),IF(_xlpm.v="","",_xlpm.v/100))} | X5: {=_xlfn.LET(_xlpm.v,_xlfn.XLOOKUP(_xlfn.ANCHORARRAY($A$5),CPI_Downloader!$A$2:$A$5000,CPI_Downloader!$K$2:$K$5000,""),IF(_xlpm.v="","",_xlpm.v))} | Z5: {=_xlfn.LET(_xlpm.v,_xlfn.XLOOKUP(_xlfn.ANCHORARRAY($A$5),CPI_Downloader!$A$2:$A$5000,CPI_Downloader!$M$2:$M$5000,""),IF(_xlpm.v="","",_xlpm.v/100))} | AA5: {=_xlfn.LET(_xlpm.v,_xlfn.XLOOKUP(_xlfn.ANCHORARRAY($A$5),CPI_Downloader!$A$2:$A$5000,CPI_Downloader!$M$2:$M$5000,""),IF(_xlpm.v="","",_xlpm.v))} | AB5: {=_xlfn.LET(_xlpm.v,_xlfn.XLOOKUP(_xlfn.ANCHORARRAY($A$5),CPI_Downloader!$A$2:$A$5000,CPI_Downloader!$L$2:$L$5000,""),IF(_xlpm.v="","",_xlpm.v/100))} | AD5: 0 | AF5: {=_xlfn.MAP(_xlfn.ANCHORARRAY($A$5),_xlfn.LAMBDA(_xlpm.d,_xlfn.LET(_xlpm.v,_xlfn.XLOOKUP(_xlpm.d,CPI_Downloader!$A$2:$A$5000,CPI_Downloader!$N$2:$N$5000,""),_xlpm.p,_xlfn.XLOOKUP(EDATE(_xlpm.d,-1),CPI_Downloader!$A$2:$A$5000,CPI_Downloader!$N$2:$N$5000,""),IF(OR(_xlpm.v="",_xlpm.p=""),"",IFERROR(_xlpm.v/_xlpm.p-1,"")))))} | AG5: {=_xlfn.LET(_xlpm.v,_xlfn.XLOOKUP(_xlfn.ANCHORARRAY($A$5),CPI_Downloader!$A$2:$A$5000,CPI_Downloader!$N$2:$N$5000,""),IF(_xlpm.v="","",_xlpm.v))} | AI5: {=_xlfn.LET(_xlpm.v,_xlfn.XLOOKUP(_xlfn.ANCHORARRAY($A$5),CPI_Downloader!$A$2:$A$5000,CPI_Downloader!$O$2:$O$5000,""),IF(_xlpm.v="","",_xlpm.v))} | AJ5: {=_xlfn.LET(_xlpm.v,_xlfn.XLOOKUP(_xlfn.ANCHORARRAY($A$5),CPI_Downloader!$A$2:$A$5000,CPI_Downloader!$P$2:$P$5000,""),IF(_xlpm.v="","",_xlpm.v))} | AK5: {=_xlfn.LET(_xlpm.v,_xlfn.XLOOKUP(_xlfn.ANCHORARRAY($A$5),CPI_Downloader!$A$2:$A$5000,CPI_Downloader!$Q$2:$Q$5000,""),IF(_xlpm.v="","",_xlpm.v))} | AM5: {=_xlfn.MAP(_xlfn.ANCHORARRAY($A$5),_xlfn.LAMBDA(_xlpm.d,_xlfn.LET(_xlpm.v,_xlfn.XLOOKUP(_xlpm.d,CPI_Downloader!$A$2:$A$5000,CPI_Downloader!$R$2:$R$5000,""),_xlpm.p,_xlfn.XLOOKUP(EDATE(_xlpm.d,-12),CPI_Downloader!$A$2:$A$5000,CPI_Downloader!$R$2:$R$5000,""),IF(OR(_xlpm.v="",_xlpm.p=""),"",IFERROR(_xlpm.v/_xlpm.p-1,"")))))} | AN5: {=_xlfn.MAP(_xlfn.ANCHORARRAY($A$5),_xlfn.LAMBDA(_xlpm.d,_xlfn.LET(_xlpm.v,_xlfn.XLOOKUP(_xlpm.d,CPI_Downloader!$A$2:$A$5000,CPI_Downloader!$R$2:$R$5000,""),_xlpm.p,_xlfn.XLOOKUP(EDATE(_xlpm.d,-1),CPI_Downloader!$A$2:$A$5000,CPI_Downloader!$R$2:$R$5000,""),IF(OR(_xlpm.v="",_xlpm.p=""),"",IFERROR(_xlpm.v/_xlpm.p-1,"")))))} | AO5: {=_xlfn.MAP(_xlfn.ANCHORARRAY($A$5),_xlfn.LAMBDA(_xlpm.d,_xlfn.LET(_xlpm.v,_xlfn.XLOOKUP(_xlpm.d,CPI_Downloader!$A$2:$A$5000,CPI_Downloader!$R$2:$R$5000,""),_xlpm.p,_xlfn.XLOOKUP(EDATE(_xlpm.d,-36),CPI_Downloader!$A$2:$A$5000,CPI_Downloader!$R$2:$R$5000,""),IF(OR(_xlpm.v="",_xlpm.p=""),"",IFERROR((_xlpm.v/_xlpm.p)^(1/3)-1,"")))))} | AP5: {=_xlfn.MAP(_xlfn.ANCHORARRAY($A$5),_xlfn.LAMBDA(_xlpm.d,_xlfn.LET(_xlpm.v,_xlfn.XLOOKUP(_xlpm.d,CPI_Downloader!$A$2:$A$5000,CPI_Downloader!$R$2:$R$5000,""),_xlpm.p,_xlfn.XLOOKUP(EDATE(_xlpm.d,-60),CPI_Downloader!$A$2:$A$5000,CPI_Downloader!$R$2:$R$5000,""),IF(OR(_xlpm.v="",_xlpm.p=""),"",IFERROR((_xlpm.v/_xlpm.p)^(1/5)-1,"")))))} | AQ5: {=_xlfn.MAP(_xlfn.ANCHORARRAY($A$5),_xlfn.LAMBDA(_xlpm.d,_xlfn.LET(_xlpm.v,_xlfn.XLOOKUP(_xlpm.d,CPI_Downloader!$A$2:$A$5000,CPI_Downloader!$R$2:$R$5000,""),_xlpm.p,_xlfn.XLOOKUP(EDATE(_xlpm.d,-120),CPI_Downloader!$A$2:$A$5000,CPI_Downloader!$R$2:$R$5000,""),IF(OR(_xlpm.v="",_xlpm.p=""),"",IFERROR((_xlpm.v/_xlpm.p)^(1/10)-1,"")))))} | AR5: {=_xlfn.MAP(_xlfn.ANCHORARRAY($A$5),_xlfn.LAMBDA(_xlpm.d,_xlfn.LET(_xlpm.v,_xlfn.XLOOKUP(_xlpm.d,CPI_Downloader!$A$2:$A$5000,CPI_Downloader!$R$2:$R$5000,""),_xlpm.p,IFERROR(_xlfn.XLOOKUP(EDATE(_xlpm.d,-240),CPI_Downloader!$A$2:$A$5000,CPI_Downloader!$R$2:$R$5000,""),""),IF(OR(_xlpm.v="",_xlpm.p=""),"",IFERROR((_xlpm.v/_xlpm.p)^(1/20)-1,"")))))} | AS5: {=_xlfn.LET(_xlpm.v,_xlfn.XLOOKUP(_xlfn.ANCHORARRAY($A$5),CPI_Downloader!$A$2:$A$5000,CPI_Downloader!$R$2:$R$5000,""),IF(_xlpm.v="","",_xlpm.v))} | AU5: {=_xlfn.MAP(_xlfn.ANCHORARRAY($A$5),_xlfn.LAMBDA(_xlpm.d,_xlfn.LET(_xlpm.v,_xlfn.XLOOKUP(_xlpm.d,CPI_Downloader!$A$2:$A$5000,CPI_Downloader!$S$2:$S$5000,""),_xlpm.p,_xlfn.XLOOKUP(EDATE(_xlpm.d,-12),CPI_Downloader!$A$2:$A$5000,CPI_Downloader!$S$2:$S$5000,""),IF(OR(_xlpm.v="",_xlpm.p=""),"",IFERROR(_xlpm.v/_xlpm.p-1,"")))))} | AV5: {=_xlfn.MAP(_xlfn.ANCHORARRAY($A$5),_xlfn.LAMBDA(_xlpm.d,_xlfn.LET(_xlpm.v,_xlfn.XLOOKUP(_xlpm.d,CPI_Downloader!$A$2:$A$5000,CPI_Downloader!$S$2:$S$5000,""),_xlpm.p,_xlfn.XLOOKUP(EDATE(_xlpm.d,-1),CPI_Downloader!$A$2:$A$5000,CPI_Downloader!$S$2:$S$5000,""),IF(OR(_xlpm.v="",_xlpm.p=""),"",IFERROR(_xlpm.v/_xlpm.p-1,"")))))} | AW5: {=_xlfn.MAP(_xlfn.ANCHORARRAY($A$5),_xlfn.LAMBDA(_xlpm.d,_xlfn.LET(_xlpm.v,_xlfn.XLOOKUP(_xlpm.d,CPI_Downloader!$A$2:$A$5000,CPI_Downloader!$S$2:$S$5000,""),_xlpm.p,_xlfn.XLOOKUP(EDATE(_xlpm.d,-36),CPI_Downloader!$A$2:$A$5000,CPI_Downloader!$S$2:$S$5000,""),IF(OR(_xlpm.v="",_xlpm.p=""),"",IFERROR((_xlpm.v/_xlpm.p)^(1/3)-1,"")))))} | AX5: {=_xlfn.MAP(_xlfn.ANCHORARRAY($A$5),_xlfn.LAMBDA(_xlpm.d,_xlfn.LET(_xlpm.v,_xlfn.XLOOKUP(_xlpm.d,CPI_Downloader!$A$2:$A$5000,CPI_Downloader!$S$2:$S$5000,""),_xlpm.p,_xlfn.XLOOKUP(EDATE(_xlpm.d,-60),CPI_Downloader!$A$2:$A$5000,CPI_Downloader!$S$2:$S$5000,""),IF(OR(_xlpm.v="",_xlpm.p=""),"",IFERROR((_xlpm.v/_xlpm.p)^(1/5)-1,"")))))} | AY5: {=_xlfn.MAP(_xlfn.ANCHORARRAY($A$5),_xlfn.LAMBDA(_xlpm.d,_xlfn.LET(_xlpm.v,_xlfn.XLOOKUP(_xlpm.d,CPI_Downloader!$A$2:$A$5000,CPI_Downloader!$S$2:$S$5000,""),_xlpm.p,_xlfn.XLOOKUP(EDATE(_xlpm.d,-120),CPI_Downloader!$A$2:$A$5000,CPI_Downloader!$S$2:$S$5000,""),IF(OR(_xlpm.v="",_xlpm.p=""),"",IFERROR((_xlpm.v/_xlpm.p)^(1/10)-1,"")))))} | AZ5: {=_xlfn.MAP(_xlfn.ANCHORARRAY($A$5),_xlfn.LAMBDA(_xlpm.d,_xlfn.LET(_xlpm.v,_xlfn.XLOOKUP(_xlpm.d,CPI_Downloader!$A$2:$A$5000,CPI_Downloader!$S$2:$S$5000,""),_xlpm.p,IFERROR(_xlfn.XLOOKUP(EDATE(_xlpm.d,-240),CPI_Downloader!$A$2:$A$5000,CPI_Downloader!$S$2:$S$5000,""),""),IF(OR(_xlpm.v="",_xlpm.p=""),"",IFERROR((_xlpm.v/_xlpm.p)^(1/20)-1,"")))))} | BA5: {=_xlfn.LET(_xlpm.v,_xlfn.XLOOKUP(_xlfn.ANCHORARRAY($A$5),CPI_Downloader!$A$2:$A$5000,CPI_Downloader!$S$2:$S$5000,""),IF(_xlpm.v="","",_xlpm.v))}
A6: 4781 | I6: 9.8 | AD6: 1
A7: 4809 | I7: 9.8 | AD7: 1
A8: 4840 | I8: 9.8 | AD8: 1
A9: 4870 | I9: 9.7 | AD9: 1
A10: 4901 | I10: 9.8 | AD10: 1
A11: 4931 | I11: 9.9 | AD11: 1
A12: 4962 | I12: 9.9 | AD12: 1
A13: 4993 | I13: 10 | AD13: 1
A14: 5023 | I14: 10 | AD14: 1
A15: 5054 | I15: 10.1 | AD15: 1
A16: 5084 | I16: 10 | AD16: 1
A17: 5115 | B17: 0.020408163 | I17: 10 | AD17: 1
A18: 5146 | B18: 0.010204082 | I18: 9.9 | AD18: 1
A19: 5174 | B19: 0.010204082 | I19: 9.9 | AD19: 1
A20: 5205 | B20: 0 | I20: 9.8 | AD20: 1
A21: 5235 | B21: 0.020618557 | I21: 9.9 | AD21: 1
A22: 5266 | B22: 0.010204082 | I22: 9.9 | AD22: 1
A23: 5296 | B23: 0.01010101 | I23: 10 | AD23: 1
A24: 5327 | B24: 0.03030303 | I24: 10.2 | AD24: 1
A25: 5358 | B25: 0.02 | I25: 10.2 | AD25: 1
A26: 5388 | B26: 0.01 | I26: 10.1 | AD26: 1
A27: 5419 | B27: 0.0099009901 | I27: 10.2 | AD27: 1
A28: 5449 | B28: 0.01 | I28: 10.1 | AD28: 1
A29: 5480 | B29: 0.01 | H29: 0.016666667 | I29: 10.1 | AD29: 0
A30: 5511 | B30: 0.01010101 | H30: 0.016666667 | I30: 10 | AD30: 0
A31: 5539 | B31: 0 | H31: 0.016666667 | I31: 9.9 | AD31: 0
A32: 5570 | B32: 0.020408163 | H32: 0.016666667 | I32: 10 | AD32: 0
A33: 5600 | B33: 0.02020202 | H33: 0.033898305 | I33: 10.1 | AD33: 0
A34: 5631 | B34: 0.02020202 | H34: 0.016666667 | I34: 10.1 | AD34: 0
A35: 5661 | B35: 0.01 | H35: 0.033898305 | I35: 10.1 | AD35: 0
A36: 5692 | B36: -0.0098039216 | H36: 0.016666667 | I36: 10.1 | AD36: 0
A37: 5723 | B37: -0.0098039216 | H37: 0.016666667 | I37: 10.1 | AD37: 0
A38: 5753 | B38: 0.0099009901 | H38: 0 | I38: 10.2 | AD38: 0
A39: 5784 | B39: 0.0098039216 | H39: 0.032786885 | I39: 10.3 | AD39: 0
A40: 5814 | B40: 0.01980198 | H40: 0.032786885 | I40: 10.3 | AD40: 0
...

Sheet CDN Data
A1: SA = Seasonally Adjusted | B1: Headline = All Items | J1: http://www150.statcan.gc.ca/t1/tbl1/en/tv.action?pid=1810000401 | L1: Core = Food/ Energy excluded | V1: Provincial = Alberta
A2: U - Unadjusted | J2: http://www150.statcan.gc.ca/t1/tbl1/en/tv.action?pid=1810000601
A3: Extra Notes/Details
A4: Month | B4: Annual Headline CPI - U | C4: Monthly Headline CPI - SA | D4: 3yr Headline CPI - U | E4: 5yr Headline CPI - U | F4: 10yr Headline CPI - U | G4: 20yr Headline CPI - U | H4: US Annual Headline CPI - U | I4: Headline CPI - U - DATA | J4: Headline CPI - SA - DATA | L4: Annual Core CPI - U | M4: Monthly Core CPI - SA | N4: 3yr Core CPI - U | O4: 5yr Core CPI - U | P4: 10yr Core CPI - U | Q4: 20yr Core CPI - U | R4: US Annual Core CPI - U | S4: Core CPI - U - DATA | T4: Core CPI - SA - DATA | V4: Annual Headline CPI Alberta- U | W4: 3yr Headline CPI Alberta - U | X4: 5yr Headline CPI Alberta - U | Y4: 10yr Headline CPI Alberta - U | Z4: 20yr Headline CPI Alberta - U | AA4: Headline CPI Alberta - U - DATA
A5: {=_xlfn.LET(_xlpm.Dates,CPI_Downloader!$A$2:$A$5000,_xlpm.Data,CPI_Downloader!$B$2:$S$5000,_xlfn._xlws.FILTER(_xlpm.Dates,_xlfn.BYROW(_xlpm.Data,_xlfn.LAMBDA(_xlpm.r,COUNT(_xlpm.r)>0)),""))} -> 4750 | B5: {=_xlfn.MAP(_xlfn.ANCHORARRAY($A$5),_xlfn.LAMBDA(_xlpm.d,_xlfn.LET(_xlpm.v,_xlfn.XLOOKUP(_xlpm.d,CPI_Downloader!$A$2:$A$5000,CPI_Downloader!$B$2:$B$5000,""),_xlpm.p,IFERROR(_xlfn.XLOOKUP(EDATE(_xlpm.d,-12),CPI_Downloader!$A$2:$A$5000,CPI_Downloader!$B$2:$B$5000,""),""),IF(OR(_xlpm.v="",_xlpm.p=""),"",IFERROR(_xlpm.v/_xlpm.p-1,"")))))} | C5: {=_xlfn.MAP(_xlfn.ANCHORARRAY($A$5),_xlfn.LAMBDA(_xlpm.d,_xlfn.LET(_xlpm.v,_xlfn.XLOOKUP(_xlpm.d,CPI_Downloader!$A$2:$A$5000,CPI_Downloader!$C$2:$C$5000,""),_xlpm.p,IFERROR(_xlfn.XLOOKUP(EDATE(_xlpm.d,-1),CPI_Downloader!$A$2:$A$5000,CPI_Downloader!$C$2:$C$5000,""),""),IF(OR(_xlpm.v="",_xlpm.p=""),"",IFERROR(_xlpm.v/_xlpm.p-1,"")))))} | D5: {=_xlfn.MAP(_xlfn.ANCHORARRAY($A$5),_xlfn.LAMBDA(_xlpm.d,_xlfn.LET(_xlpm.v,_xlfn.XLOOKUP(_xlpm.d,CPI_Downloader!$A$2:$A$5000,CPI_Downloader!$B$2:$B$5000,""),_xlpm.p,IFERROR(_xlfn.XLOOKUP(EDATE(_xlpm.d,-36),CPI_Downloader!$A$2:$A$5000,CPI_Downloader!$B$2:$B$5000,""),""),IF(OR(_xlpm.v="",_xlpm.p=""),"",IFERROR((_xlpm.v/_xlpm.p)^(1/3)-1,"")))))} | E5: {=_xlfn.MAP(_xlfn.ANCHORARRAY($A$5),_xlfn.LAMBDA(_xlpm.d,_xlfn.LET(_xlpm.v,_xlfn.XLOOKUP(_xlpm.d,CPI_Downloader!$A$2:$A$5000,CPI_Downloader!$B$2:$B$5000,""),_xlpm.p,IFERROR(_xlfn.XLOOKUP(EDATE(_xlpm.d,-60),CPI_Downloader!$A$2:$A$5000,CPI_Downloader!$B$2:$B$5000,""),""),IF(OR(_xlpm.v="",_xlpm.p=""),"",IFERROR((_xlpm.v/_xlpm.p)^(1/5)-1,"")))))} | F5: {=_xlfn.MAP(_xlfn.ANCHORARRAY($A$5),_xlfn.LAMBDA(_xlpm.d,_xlfn.LET(_xlpm.v,_xlfn.XLOOKUP(_xlpm.d,CPI_Downloader!$A$2:$A$5000,CPI_Downloader!$B$2:$B$5000,""),_xlpm.p,IFERROR(_xlfn.XLOOKUP(EDATE(_xlpm.d,-120),CPI_Downloader!$A$2:$A$5000,CPI_Downloader!$B$2:$B$5000,""),""),IF(OR(_xlpm.v="",_xlpm.p=""),"",IFERROR((_xlpm.v/_xlpm.p)^(1/10)-1,"")))))} | G5: {=_xlfn.MAP(_xlfn.ANCHORARRAY($A$5),_xlfn.LAMBDA(_xlpm.d,_xlfn.LET(_xlpm.v,_xlfn.XLOOKUP(_xlpm.d,CPI_Downloader!$A$2:$A$5000,CPI_Downloader!$B$2:$B$5000,""),_xlpm.p,IFERROR(_xlfn.XLOOKUP(EDATE(_xlpm.d,-240),CPI_Downloader!$A$2:$A$5000,CPI_Downloader!$B$2:$B$5000,""),""),IF(OR(_xlpm.v="",_xlpm.p=""),"",IFERROR((_xlpm.v/_xlpm.p)^(1/20)-1,"")))))} | H5: {=_xlfn.MAP(_xlfn.ANCHORARRAY($A$5),_xlfn.LAMBDA(_xlpm.d,_xlfn.LET(_xlpm.v,_xlfn.XLOOKUP(_xlpm.d,CPI_Downloader!$A$2:$A$5000,CPI_Downloader!$G$2:$G$5000,""),_xlpm.p,IFERROR(_xlfn.XLOOKUP(EDATE(_xlpm.d,-12),CPI_Downloader!$A$2:$A$5000,CPI_Downloader!$G$2:$G$5000,""),""),IF(OR(_xlpm.v="",_xlpm.p=""),"",IFERROR(_xlpm.v/_xlpm.p-1,"")))))} | I5: {=_xlfn.LET(_xlpm.v,_xlfn.XLOOKUP(_xlfn.ANCHORARRAY($A$5),CPI_Downloader!$A$2:$A$5000,CPI_Downloader!$B$2:$B$5000,""),IF(_xlpm.v="","",_xlpm.v))} | J5: {=_xlfn.LET(_xlpm.v,_xlfn.XLOOKUP(_xlfn.ANCHORARRAY($A$5),CPI_Downloader!$A$2:$A$5000,CPI_Downloader!$C$2:$C$5000,""),IF(_xlpm.v="","",_xlpm.v))} | L5: {=_xlfn.MAP(_xlfn.ANCHORARRAY($A$5),_xlfn.LAMBDA(_xlpm.d,_xlfn.LET(_xlpm.v,_xlfn.XLOOKUP(_xlpm.d,CPI_Downloader!$A$2:$A$5000,CPI_Downloader!$D$2:$D$5000,""),_xlpm.p,IFERROR(_xlfn.XLOOKUP(EDATE(_xlpm.d,-12),CPI_Downloader!$A$2:$A$5000,CPI_Downloader!$D$2:$D$5000,""),""),IF(OR(_xlpm.v="",_xlpm.p=""),"",IFERROR(_xlpm.v/_xlpm.p-1,"")))))} | M5: {=_xlfn.MAP(_xlfn.ANCHORARRAY($A$5),_xlfn.LAMBDA(_xlpm.d,_xlfn.LET(_xlpm.v,_xlfn.XLOOKUP(_xlpm.d,CPI_Downloader!$A$2:$A$5000,CPI_Downloader!$E$2:$E$5000,""),_xlpm.p,IFERROR(_xlfn.XLOOKUP(EDATE(_xlpm.d,-1),CPI_Downloader!$A$2:$A$5000,CPI_Downloader!$E$2:$E$5000,""),""),IF(OR(_xlpm.v="",_xlpm.p=""),"",IFERROR(_xlpm.v/_xlpm.p-1,"")))))} | N5: {=_xlfn.MAP(_xlfn.ANCHORARRAY($A$5),_xlfn.LAMBDA(_xlpm.d,_xlfn.LET(_xlpm.v,_xlfn.XLOOKUP(_xlpm.d,CPI_Downloader!$A$2:$A$5000,CPI_Downloader!$D$2:$D$5000,""),_xlpm.p,IFERROR(_xlfn.XLOOKUP(EDATE(_xlpm.d,-36),CPI_Downloader!$A$2:$A$5000,CPI_Downloader!$D$2:$D$5000,""),""),IF(OR(_xlpm.v="",_xlpm.p=""),"",IFERROR((_xlpm.v/_xlpm.p)^(1/3)-1,"")))))} | O5: {=_xlfn.MAP(_xlfn.ANCHORARRAY($A$5),_xlfn.LAMBDA(_xlpm.d,_xlfn.LET(_xlpm.v,_xlfn.XLOOKUP(_xlpm.d,CPI_Downloader!$A$2:$A$5000,CPI_Downloader!$D$2:$D$5000,""),_xlpm.p,IFERROR(_xlfn.XLOOKUP(EDATE(_xlpm.d,-60),CPI_Downloader!$A$2:$A$5000,CPI_Downloader!$D$2:$D$5000,""),""),IF(OR(_xlpm.v="",_xlpm.p=""),"",IFERROR((_xlpm.v/_xlpm.p)^(1/5)-1,"")))))} | P5: {=_xlfn.MAP(_xlfn.ANCHORARRAY($A$5),_xlfn.LAMBDA(_xlpm.d,_xlfn.LET(_xlpm.v,_xlfn.XLOOKUP(_xlpm.d,CPI_Downloader!$A$2:$A$5000,CPI_Downloader!$D$2:$D$5000,""),_xlpm.p,IFERROR(_xlfn.XLOOKUP(EDATE(_xlpm.d,-120),CPI_Downloader!$A$2:$A$5000,CPI_Downloader!$D$2:$D$5000,""),""),IF(OR(_xlpm.v="",_xlpm.p=""),"",IFERROR((_xlpm.v/_xlpm.p)^(1/10)-1,"")))))} | Q5: {=_xlfn.MAP(_xlfn.ANCHORARRAY($A$5),_xlfn.LAMBDA(_xlpm.d,_xlfn.LET(_xlpm.v,_xlfn.XLOOKUP(_xlpm.d,CPI_Downloader!$A$2:$A$5000,CPI_Downloader!$D$2:$D$5000,""),_xlpm.p,IFERROR(_xlfn.XLOOKUP(EDATE(_xlpm.d,-240),CPI_Downloader!$A$2:$A$5000,CPI_Downloader!$D$2:$D$5000,""),""),IF(OR(_xlpm.v="",_xlpm.p=""),"",IFERROR((_xlpm.v/_xlpm.p)^(1/20)-1,"")))))} | R5: {=_xlfn.MAP(_xlfn.ANCHORARRAY($A$5),_xlfn.LAMBDA(_xlpm.d,_xlfn.LET(_xlpm.v,_xlfn.XLOOKUP(_xlpm.d,CPI_Downloader!$A$2:$A$5000,CPI_Downloader!$I$2:$I$5000,""),_xlpm.p,IFERROR(_xlfn.XLOOKUP(EDATE(_xlpm.d,-12),CPI_Downloader!$A$2:$A$5000,CPI_Downloader!$I$2:$I$5000,""),""),IF(OR(_xlpm.v="",_xlpm.p=""),"",IFERROR(_xlpm.v/_xlpm.p-1,"")))))} | S5: {=_xlfn.LET(_xlpm.v,_xlfn.XLOOKUP(_xlfn.ANCHORARRAY($A$5),CPI_Downloader!$A$2:$A$5000,CPI_Downloader!$D$2:$D$5000,""),IF(_xlpm.v="","",_xlpm.v))} | T5: {=_xlfn.LET(_xlpm.v,_xlfn.XLOOKUP(_xlfn.ANCHORARRAY($A$5),CPI_Downloader!$A$2:$A$5000,CPI_Downloader!$E$2:$E$5000,""),IF(_xlpm.v="","",_xlpm.v))} | V5: {=_xlfn.MAP(_xlfn.ANCHORARRAY($A$5),_xlfn.LAMBDA(_xlpm.d,_xlfn.LET(_xlpm.v,_xlfn.XLOOKUP(_xlpm.d,CPI_Downloader!$A$2:$A$5000,CPI_Downloader!$F$2:$F$5000,""),_xlpm.p,IFERROR(_xlfn.XLOOKUP(EDATE(_xlpm.d,-12),CPI_Downloader!$A$2:$A$5000,CPI_Downloader!$F$2:$F$5000,""),""),IF(OR(_xlpm.v="",_xlpm.p=""),"",IFERROR(_xlpm.v/_xlpm.p-1,"")))))} | W5: {=_xlfn.MAP(_xlfn.ANCHORARRAY($A$5),_xlfn.LAMBDA(_xlpm.d,_xlfn.LET(_xlpm.v,_xlfn.XLOOKUP(_xlpm.d,CPI_Downloader!$A$2:$A$5000,CPI_Downloader!$F$2:$F$5000,""),_xlpm.p,IFERROR(_xlfn.XLOOKUP(EDATE(_xlpm.d,-36),CPI_Downloader!$A$2:$A$5000,CPI_Downloader!$F$2:$F$5000,""),""),IF(OR(_xlpm.v="",_xlpm.p=""),"",IFERROR((_xlpm.v/_xlpm.p)^(1/3)-1,"")))))} | X5: {=_xlfn.MAP(_xlfn.ANCHORARRAY($A$5),_xlfn.LAMBDA(_xlpm.d,_xlfn.LET(_xlpm.v,_xlfn.XLOOKUP(_xlpm.d,CPI_Downloader!$A$2:$A$5000,CPI_Downloader!$F$2:$F$5000,""),_xlpm.p,IFERROR(_xlfn.XLOOKUP(EDATE(_xlpm.d,-60),CPI_Downloader!$A$2:$A$5000,CPI_Downloader!$F$2:$F$5000,""),""),IF(OR(_xlpm.v="",_xlpm.p=""),"",IFERROR((_xlpm.v/_xlpm.p)^(1/5)-1,"")))))} | Y5: {=_xlfn.MAP(_xlfn.ANCHORARRAY($A$5),_xlfn.LAMBDA(_xlpm.d,_xlfn.LET(_xlpm.v,_xlfn.XLOOKUP(_xlpm.d,CPI_Downloader!$A$2:$A$5000,CPI_Downloader!$F$2:$F$5000,""),_xlpm.p,IFERROR(_xlfn.XLOOKUP(EDATE(_xlpm.d,-120),CPI_Downloader!$A$2:$A$5000,CPI_Downloader!$F$2:$F$5000,""),""),IF(OR(_xlpm.v="",_xlpm.p=""),"",IFERROR((_xlpm.v/_xlpm.p)^(1/10)-1,"")))))} | Z5: {=_xlfn.MAP(_xlfn.ANCHORARRAY($A$5),_xlfn.LAMBDA(_xlpm.d,_xlfn.LET(_xlpm.v,_xlfn.XLOOKUP(_xlpm.d,CPI_Downloader!$A$2:$A$5000,CPI_Downloader!$F$2:$F$5000,""),_xlpm.p,IFERROR(_xlfn.XLOOKUP(EDATE(_xlpm.d,-240),CPI_Downloader!$A$2:$A$5000,CPI_Downloader!$F$2:$F$5000,""),""),IF(OR(_xlpm.v="",_xlpm.p=""),"",IFERROR((_xlpm.v/_xlpm.p)^(1/20)-1,"")))))} | AA5: {=_xlfn.LET(_xlpm.v,_xlfn.XLOOKUP(_xlfn.ANCHORARRAY($A$5),CPI_Downloader!$A$2:$A$5000,CPI_Downloader!$F$2:$F$5000,""),IF(_xlpm.v="","",_xlpm.v))}
A6: 4781
A7: 4809
A8: 4840
A9: 4870
A10: 4901
A11: 4931
A12: 4962
A13: 4993
A14: 5023
A15: 5054
A16: 5084
A17: 5115 | H17: 0.020408163 | I17: 6
A18: 5146 | H18: 0.010204082 | I18: 6
A19: 5174 | H19: 0.010204082 | I19: 6
A20: 5205 | H20: 0 | I20: 6
A21: 5235 | H21: 0.020618557 | I21: 5.9
A22: 5266 | H22: 0.010204082 | I22: 6
A23: 5296 | H23: 0.01010101 | I23: 5.9
A24: 5327 | H24: 0.03030303 | I24: 6
A25: 5358 | H25: 0.02 | I25: 6
A26: 5388 | H26: 0.01 | I26: 6.1
A27: 5419 | H27: 0.0099009901 | I27: 6.1
A28: 5449 | H28: 0.01 | I28: 6.1
A29: 5480 | B29: 0.016666667 | H29: 0.01 | I29: 6.1
A30: 5511 | B30: 0.016666667 | H30: 0.01010101 | I30: 6.1
A31: 5539 | B31: 0.016666667 | H31: 0 | I31: 6.1
A32: 5570 | B32: 0.016666667 | H32: 0.020408163 | I32: 6.1
A33: 5600 | B33: 0.033898305 | H33: 0.02020202 | I33: 6.1
A34: 5631 | B34: 0.016666667 | H34: 0.02020202 | I34: 6.1
A35: 5661 | B35: 0.033898305 | H35: 0.01 | I35: 6.1
A36: 5692 | B36: 0.016666667 | H36: -0.0098039216 | I36: 6.1
A37: 5723 | B37: 0.016666667 | H37: -0.0098039216 | I37: 6.1
A38: 5753 | B38: 0 | H38: 0.0099009901 | I38: 6.1
A39: 5784 | B39: 0.032786885 | H39: 0.0098039216 | I39: 6.3
A40: 5814 | B40: 0.032786885 | H40: 0.01980198 | I40: 6.3
...

Sheet Data Visualizations
B2: US Headline CPI | E2: Start Date | F2: 36526 | H2: End Date | I2: =TODAY() -> 46280 | T2: Canadian Headline CPI | X2: Start Date | Y2: 36526 | AA2: End Date | AB2: =TODAY() -> 46280 | AI2: US Recessions, Unemployment, Fed Funds & S&P 500 | AR2: Start Date | AS2: 36526 | AU2: End Date | AV2: =TODAY() -> 46280
CQ4: Month | CR4: Monthly CPI - SA | CS4: Annual CPI - U | CT4: US Recession | CV4: Month | CW4: Monthly CDN Headline CPI - SA | CX4: Annual CDN Headline CPI - U | CY4: Annual Alberta Headline CPI - U | DA4: Month | DB4: Monthly US Core CPI - SA | DC4: Annual US Core CPI - U | DE4: Month | DF4: Monthly CDN Core CPI - SA | DG4: Annual CDN Core CPI - U | DI4: Month | DJ4: Recession Shade | DK4: Monthly Unemployment - SA | DL4: Effective Fed Funds Rate - Monthly Avg | DM4: S&P 500 (EOM) | DO4: Chart Axis Setting | DP4: Value | DR4: US Recession Shade (Lower)
CQ5: {=_xlfn.LET( _xlpm.d,_xlfn.ANCHORARRAY('US Data'!$A$5), _xlpm.a,_xlfn.ANCHORARRAY('US Data'!$B$5), _xlpm.m,_xlfn.ANCHORARRAY('US Data'!$C$5), _xlpm.base,_xlfn._xlws.FILTER(_xlpm.d,((_xlpm.a<>"")+(_xlpm.m<>""))>0), _xlpm.s,$F$2, _xlpm.e,$I$2, _xlpm.valid,IFERROR(AND(ISNUMBER(_xlpm.s),ISNUMBER(_xlpm.e),_xlpm.s<=_xlpm.e),FALSE), _xlpm.lo,MIN(_xlpm.base), _xlpm.hi,MAX(_xlpm.base), _xlpm.startDate,MAX(_xlpm.lo,MIN(IF(ISNUMBER(_xlpm.s),_xlpm.s,_xlpm.lo),_xlpm.hi)), _xlpm.endDate,MAX(_xlpm.lo,MIN(IF(ISNUMBER(_xlpm.e),_xlpm.e,_xlpm.hi),_xlpm.hi)), IF(_xlpm.valid,_xlfn._xlws.FILTER(_xlpm.base,(_xlpm.base>=_xlpm.startDate)*(_xlpm.base<=_xlpm.endDate)),_xlpm.base) )} -> 36526 | CR5: {=_xlfn.LET(_xlpm.v,_xlfn.XLOOKUP(_xlfn.ANCHORARRAY(CQ5),_xlfn.ANCHORARRAY('US Data'!$A$5),_xlfn.ANCHORARRAY('US Data'!$C$5),""),IF(_xlpm.v="",NA(),_xlpm.v))} -> 0.0029620853 | CS5: {=_xlfn.LET(_xlpm.v,_xlfn.XLOOKUP(_xlfn.ANCHORARRAY(CQ5),_xlfn.ANCHORARRAY('US Data'!$A$5),_xlfn.ANCHORARRAY('US Data'!$B$5),""),IF(_xlpm.v="",NA(),_xlpm.v))} -> 0.027388923 | CT5: {=_xlfn.LET(_xlpm.r,_xlfn.XLOOKUP(_xlfn.ANCHORARRAY(CQ5),_xlfn.ANCHORARRAY('US Data'!$A$5),_xlfn.TAKE('US Data'!$AD$5:$AD$5000,ROWS(_xlfn.ANCHORARRAY('US Data'!$A$5))),""),IF(_xlpm.r=1,1,NA()))} -> #N/A | CV5: {=_xlfn.LET( _xlpm.d,_xlfn.ANCHORARRAY('CDN Data'!$A$5), _xlpm.a,_xlfn.ANCHORARRAY('CDN Data'!$B$5), _xlpm.m,_xlfn.ANCHORARRAY('CDN Data'!$C$5), _xlpm.ab,_xlfn.ANCHORARRAY('CDN Data'!$V$5), _xlpm.base,_xlfn._xlws.FILTER(_xlpm.d,((_xlpm.a<>"")+(_xlpm.m<>"")+(_xlpm.ab<>""))>0), _xlpm.s,$Y$2, _xlpm.e,$AB$2, _xlpm.valid,IFERROR(AND(ISNUMBER(_xlpm.s),ISNUMBER(_xlpm.e),_xlpm.s<=_xlpm.e),FALSE), _xlpm.lo,MIN(_xlpm.base), _xlpm.hi,MAX(_xlpm.base), _xlpm.startDate,MAX(_xlpm.lo,MIN(IF(ISNUMBER(_xlpm.s),_xlpm.s,_xlpm.lo),_xlpm.hi)), _xlpm.endDate,MAX(_xlpm.lo,MIN(IF(ISNUMBER(_xlpm.e),_xlpm.e,_xlpm.hi),_xlpm.hi)), IF(_xlpm.valid,_xlfn._xlws.FILTER(_xlpm.base,(_xlpm.base>=_xlpm.startDate)*(_xlpm.base<=_xlpm.endDate)),_xlpm.base) )} -> 36526 | CW5: {=_xlfn.LET(_xlpm.v,_xlfn.XLOOKUP(_xlfn.ANCHORARRAY(CV5),_xlfn.ANCHORARRAY('CDN Data'!$A$5),_xlfn.ANCHORARRAY('CDN Data'!$C$5),""),IF(_xlpm.v="",NA(),_xlpm.v))} -> 0 | CX5: {=_xlfn.LET(_xlpm.v,_xlfn.XLOOKUP(_xlfn.ANCHORARRAY(CV5),_xlfn.ANCHORARRAY('CDN Data'!$A$5),_xlfn.ANCHORARRAY('CDN Data'!$B$5),""),IF(_xlpm.v="",NA(),_xlpm.v))} -> 0.021857923 | CY5: {=_xlfn.LET(_xlpm.v,_xlfn.XLOOKUP(_xlfn.ANCHORARRAY(CV5),_xlfn.ANCHORARRAY('CDN Data'!$A$5),_xlfn.ANCHORARRAY('CDN Data'!$V$5),""),IF(_xlpm.v="",NA(),_xlpm.v))} -> 0.027808676 | DA5: {=_xlfn.LET( _xlpm.d,_xlfn.ANCHORARRAY('US Data'!$A$5), _xlpm.a,_xlfn.ANCHORARRAY('US Data'!$L$5), _xlpm.m,_xlfn.ANCHORARRAY('US Data'!$M$5), _xlpm.base,_xlfn._xlws.FILTER(_xlpm.d,((_xlpm.a<>"")+(_xlpm.m<>""))>0), _xlpm.s,$F$27, _xlpm.e,$I$27, _xlpm.valid,IFERROR(AND(ISNUMBER(_xlpm.s),ISNUMBER(_xlpm.e),_xlpm.s<=_xlpm.e),FALSE), _xlpm.lo,MIN(_xlpm.base), _xlpm.hi,MAX(_xlpm.base), _xlpm.startDate,MAX(_xlpm.lo,MIN(IF(ISNUMBER(_xlpm.s),_xlpm.s,_xlpm.lo),_xlpm.hi)), _xlpm.endDate,MAX(_xlpm.lo,MIN(IF(ISNUMBER(_xlpm.e),_xlpm.e,_xlpm.hi),_xlpm.hi)), IF(_xlpm.valid,_xlfn._xlws.FILTER(_xlpm.base,(_xlpm.base>=_xlpm.startDate)*(_xlpm.base<=_xlpm.endDate)),_xlpm.base) )} -> 36526 | DB5: {=_xlfn.LET(_xlpm.v,_xlfn.XLOOKUP(_xlfn.ANCHORARRAY(DA5),_xlfn.ANCHORARRAY('US Data'!$A$5),_xlfn.ANCHORARRAY('US Data'!$M$5),""),IF(_xlpm.v="",NA(),_xlpm.v))} -> 0.0033575825 | DC5: {=_xlfn.LET(_xlpm.v,_xlfn.XLOOKUP(_xlfn.ANCHORARRAY(DA5),_xlfn.ANCHORARRAY('US Data'!$A$5),_xlfn.ANCHORARRAY('US Data'!$L$5),""),IF(_xlpm.v="",NA(),_xlpm.v))} -> 0.019965773 | DE5: {=_xlfn.LET( _xlpm.d,_xlfn.ANCHORARRAY('CDN Data'!$A$5), _xlpm.a,_xlfn.ANCHORARRAY('CDN Data'!$L$5), _xlpm.m,_xlfn.ANCHORARRAY('CDN Data'!$M$5), _xlpm.base,_xlfn._xlws.FILTER(_xlpm.d,((_xlpm.a<>"")+(_xlpm.m<>""))>0), _xlpm.s,$Y$27, _xlpm.e,$AB$27, _xlpm.valid,IFERROR(AND(ISNUMBER(_xlpm.s),ISNUMBER(_xlpm.e),_xlpm.s<=_xlpm.e),FALSE), _xlpm.lo,MIN(_xlpm.base), _xlpm.hi,MAX(_xlpm.base), _xlpm.startDate,MAX(_xlpm.lo,MIN(IF(ISNUMBER(_xlpm.s),_xlpm.s,_xlpm.lo),_xlpm.hi)), _xlpm.endDate,MAX(_xlpm.lo,MIN(IF(ISNUMBER(_xlpm.e),_xlpm.e,_xlpm.hi),_xlpm.hi)), IF(_xlpm.valid,_xlfn._xlws.FILTER(_xlpm.base,(_xlpm.base>=_xlpm.startDate)*(_xlpm.base<=_xlpm.endDate)),_xlpm.base) )} -> 36526 | DF5: {=_xlfn.LET(_xlpm.v,_xlfn.XLOOKUP(_xlfn.ANCHORARRAY(DE5),_xlfn.ANCHORARRAY('CDN Data'!$A$5),_xlfn.ANCHORARRAY('CDN Data'!$M$5),""),IF(_xlpm.v="",NA(),_xlpm.v))} -> 0 | DG5: {=_xlfn.LET(_xlpm.v,_xlfn.XLOOKUP(_xlfn.ANCHORARRAY(DE5),_xlfn.ANCHORARRAY('CDN Data'!$A$5),_xlfn.ANCHORARRAY('CDN Data'!$L$5),""),IF(_xlpm.v="",NA(),_xlpm.v))} -> 0.015086207 | DI5: {=_xlfn.LET( _xlpm.d,_xlfn.ANCHORARRAY('US Data'!$A$5), _xlpm.u,_xlfn.ANCHORARRAY('US Data'!$W$5), _xlpm.f,_xlfn.ANCHORARRAY('US Data'!$AB$5), _xlpm.sp,_xlfn.ANCHORARRAY('US Data'!$AG$5), _xlpm.base,_xlfn._xlws.FILTER(_xlpm.d,((_xlpm.u<>"")+(_xlpm.f<>"")+(_xlpm.sp<>""))>0), _xlpm.s,$AS$2, _xlpm.e,$AV$2, _xlpm.valid,IFERROR(AND(ISNUMBER(_xlpm.s),ISNUMBER(_xlpm.e),_xlpm.s<=_xlpm.e),FALSE), _xlpm.lo,MIN(_xlpm.base), _xlpm.hi,MAX(_xlpm.base), _xlpm.startDate,MAX(_xlpm.lo,MIN(IF(ISNUMBER(_xlpm.s),_xlpm.s,_xlpm.lo),_xlpm.hi)), _xlpm.endDate,MAX(_xlpm.lo,MIN(IF(ISNUMBER(_xlpm.e),_xlpm.e,_xlpm.hi),_xlpm.hi)), IF(_xlpm.valid,_xlfn._xlws.FILTER(_xlpm.base,(_xlpm.base>=_xlpm.startDate)*(_xlpm.base<=_xlpm.endDate)),_xlpm.base) )} -> 36526 | DJ5: {=_xlfn.LET(_xlpm.r,_xlfn.XLOOKUP(_xlfn.ANCHORARRAY(DI5),_xlfn.ANCHORARRAY('US Data'!$A$5),_xlfn.TAKE('US Data'!$AD$5:$AD$5000,ROWS(_xlfn.ANCHORARRAY('US Data'!$A$5))),""),IF(_xlpm.r=1,$DP$5,NA()))} -> #N/A | DK5: {=_xlfn.LET(_xlpm.v,_xlfn.XLOOKUP(_xlfn.ANCHORARRAY(DI5),_xlfn.ANCHORARRAY('US Data'!$A$5),_xlfn.ANCHORARRAY('US Data'!$W$5),""),IF(_xlpm.v="",NA(),_xlpm.v))} -> 0.04 | DL5: {=_xlfn.LET(_xlpm.v,_xlfn.XLOOKUP(_xlfn.ANCHORARRAY(DI5),_xlfn.ANCHORARRAY('US Data'!$A$5),_xlfn.ANCHORARRAY('US Data'!$AB$5),""),IF(_xlpm.v="",NA(),_xlpm.v))} -> 0.0545 | DM5: {=_xlfn.LET(_xlpm.v,_xlfn.XLOOKUP(_xlfn.ANCHORARRAY(DI5),_xlfn.ANCHORARRAY('US Data'!$A$5),_xlfn.ANCHORARRAY('US Data'!$AG$5),""),IF(_xlpm.v="",NA(),_xlpm.v))} -> #N/A | DO5: Recession/Unemployment chart - primary axis max (recession shade) | DP5: 0.3 | DR5: {=IF(ISNUMBER(_xlfn.ANCHORARRAY(CT5)),-1,NA())} -> #N/A
CQ6: 36557 | CR6: 0.0041346722 | CS6: 0.032218845 | CT6: #N/A | CV6: 36557 | CW6: 0.0031914894 | CX6: 0.027292576 | CY6: 0.026696329 | DA6: 36557 | DB6: 0.00055772448 | DC6: 0.021627775 | DE6: 36557 | DF6: 0.0021141649 | DG6: 0.016111708 | DI6: 36557 | DJ6: #N/A | DK6: 0.041 | DL6: 0.0573 | DM6: #N/A | DR6: #N/A
CQ7: 36586 | CR7: 0.0058823529 | CS7: 0.037575758 | CT7: #N/A | CV7: 36586 | CW7: 0.0053022269 | CX7: 0.030434783 | CY7: 0.035516093 | DA7: 36586 | DB7: 0.0033444816 | DC7: 0.024404086 | DE7: 36586 | DF7: 0.0021097046 | DG7: 0.016042781 | DI7: 36586 | DJ7: #N/A | DK7: 0.04 | DL7: 0.0585 | DM7: #N/A | DR7: #N/A
CQ8: 36617 | CR8: -0.00058479532 | CS8: 0.030685921 | CT8: #N/A | CV8: 36617 | CW8: -0.0042194093 | CX8: 0.021621622 | CY8: 0.033222591 | DA8: 36617 | DB8: 0.0016666667 | DC8: 0.023190045 | DE8: 36617 | DF8: 0 | DG8: 0.012793177 | DI8: 36617 | DJ8: #N/A | DK8: 0.038 | DL8: 0.0602 | DM8: #N/A | DR8: #N/A
CQ9: 36647 | CR9: 0.0017554125 | CS9: 0.03188929 | CT9: #N/A | CV9: 36647 | CW9: 0.0031779661 | CX9: 0.02373247 | CY9: 0.031868132 | DA9: 36647 | DB9: 0.0022185247 | DC9: 0.024348811 | DE9: 36647 | DF9: 0.0021052632 | DG9: 0.013829787 | DI9: 36647 | DJ9: #N/A | DK9: 0.04 | DL9: 0.0627 | DM9: #N/A | DR9: #N/A
CQ10: 36678 | CR10: 0.0058411215 | CS10: 0.037304452 | CT10: #N/A | CV10: 36678 | CW10: 0.0063357973 | CX10: 0.027987083 | CY10: 0.033991228 | DA10: 36678 | DB10: 0.0022136137 | DC10: 0.024915062 | DE10: 36678 | DF10: 0.0021008403 | DG10: 0.01487779 | DI10: 36678 | DJ10: #N/A | DK10: 0.04 | DL10: 0.0653 | DM10: #N/A | DR10: #N/A
CQ11: 36708 | CR11: 0.0029036005 | CS11: 0.036592681 | CT11: #N/A | CV11: 36708 | CW11: 0.0031479538 | CX11: 0.029001074 | CY11: 0.041575492 | DA11: 36708 | DB11: 0.0022087245 | DC11: 0.024872809 | DE11: 36708 | DF11: 0.001048218 | DG11: 0.015923567 | DI11: 36708 | DJ11: #N/A | DK11: 0.04 | DL11: 0.0654 | DM11: #N/A | DR11: #N/A
CQ12: 36739 | CR12: 0 | CS12: 0.034111311 | CT12: #N/A | CV12: 36739 | CW12: -0.0010460251 | CX12: 0.025723473 | CY12: 0.034744843 | DA12: 36739 | DB12: 0.0022038567 | DC12: 0.025974026 | DE12: 36739 | DF12: 0.0010471204 | DG12: 0.014830508 | DI12: 36739 | DJ12: #N/A | DK12: 0.041 | DL12: 0.065 | DM12: #N/A | DR12: #N/A
CQ13: 36770 | CR13: 0.0052113492 | CS13: 0.034544372 | CT13: #N/A | CV13: 36770 | CW13: 0.0041884817 | CX13: 0.026709402 | CY13: 0.035637149 | DA13: 36770 | DB13: 0.0021990104 | DC13: 0.025886325 | DE13: 36770 | DF13: 0.0020920502 | DG13: 0.012658228 | DI13: 36770 | DJ13: #N/A | DK13: 0.039 | DL13: 0.0652 | DM13: #N/A | DR13: #N/A
CQ14: 36800 | CR14: 0.0017281106 | CS14: 0.034482759 | CT14: #N/A | CV14: 36800 | CW14: 0.0041710115 | CX14: 0.027748132 | CY14: 0.035598706 | DA14: 36800 | DB14: 0.0016456391 | DC14: 0.025238362 | DE14: 36800 | DF14: 0.0010438413 | DG14: 0.014783527 | DI14: 36800 | DJ14: #N/A | DK14: 0.039 | DL14: 0.0651 | DM14: #N/A | DR14: #N/A
CQ15: 36831 | CR15: 0.0017251294 | CS15: 0.03446227 | CT15: #N/A | CV15: 36831 | CW15: 0.005192108 | CX15: 0.032051282 | CY15: 0.043336945 | DA15: 36831 | DB15: 0.0027382256 | DC15: 0.025784753 | DE15: 36831 | DF15: 0.0041710115 | DG15: 0.017989418 | DI15: 36831 | DJ15: #N/A | DK15: 0.039 | DL15: 0.0651 | DM15: #N/A | DR15: #N/A
CQ16: 36861 | CR16: 0.0022962113 | CS16: 0.033868093 | CT16: #N/A | CV16: 36861 | CW16: 0.0020661157 | CX16: 0.032017076 | CY16: 0.038834951 | DA16: 36861 | DB16: 0.0010922993 | DC16: 0.025813692 | DE16: 36861 | DF16: 0.0010384216 | DG16: 0.019067797 | DI16: 36861 | DJ16: #N/A | DK16: 0.039 | DL16: 0.064 | DM16: #N/A | DR16: #N/A
CQ17: 36892 | CR17: 0.0057273769 | CS17: 0.037322275 | CT17: #N/A | CV17: 36892 | CW17: -0.0020618557 | CX17: 0.029946524 | CY17: 0.010822511 | DA17: 36892 | DB17: 0.0032733224 | DC17: 0.026286353 | DE17: 36892 | DF17: 0.0010373444 | DG17: 0.01910828 | DI17: 36892 | DJ17: #N/A | DK17: 0.042 | DL17: 0.0598 | DM17: #N/A | DR17: #N/A
... CQ19: 36951 | CR19: 0.00056818182 | CS19: 0.029205607 | CT19: #N/A | CV19: 36951 | CW19: 0.0020639835 | CX19: 0.024261603 | CY19: 0.024651661 | DA19: 36951 | DB19: 0.001626898 | DC19: 0.026592798 | DE19: 36951 | DF19: 0 | DG19: 0.016842105 | DI19: 36951 | DJ19: #N/A | DK19: 0.043 | DL19: 0.0531 | DM19: #N/A | DR19: #N/A
CQ20: 36982 | CR20: 0.0017035775 | CS20: 0.032691185 | CT20: 1 | CV20: 36982 | CW20: 0.0072090628 | CX20: 0.034920635 | CY20: 0.025723473 | DA20: 36982 | DB20: 0.0021656741 | DC20: 0.025981205 | DE20: 36982 | DF20: 0.0031023785 | DG20: 0.021052632 | DI20: 36982 | DJ20: 0.3 | DK20: 0.044 | DL20: 0.048 | DM20: #N/A | DR20: -1
CQ21: 37012 | CR21: 0.0051020408 | CS21: 0.036151603 | CT21: 1 | CV21: 37012 | CW21: 0.0061349693 | CX21: 0.038988409 | CY21: 0.056443024 | DA21: 37012 | DB21: 0.001080497 | DC21: 0.025428413 | DE21: 37012 | DF21: 0.0010309278 | DG21: 0.020986359 | DI21: 37012 | DJ21: 0.3 | DK21: 0.043 | DL21: 0.0421 | DM21: #N/A | DR21: -1
CQ22: 37043 | CR22: 0.0022560632 | CS22: 0.032482599 | CT22: 1 | CV22: 37043 | CW22: 0 | CX22: 0.033507853 | CY22: 0.05514316 | DA22: 37043 | DB22: 0.0037776579 | DC22: 0.027071823 | DE22: 37043 | DF22: 0.0020597322 | DG22: 0.019895288 | DI22: 37043 | DJ22: 0.3 | DK22: 0.045 | DL22: 0.0397 | DM22: #N/A | DR22: -1
CQ23: 37073 | CR23: -0.0016882386 | CS23: 0.027199074 | CT23: 1 | CV23: 37073 | CW23: -0.0030487805 | CX23: 0.027139875 | CY23: 0.028361345 | DA23: 37073 | DB23: 0.0021505376 | DC23: 0.027027027 | DE23: 37073 | DF23: 0.0020554985 | DG23: 0.021943574 | DI23: 37073 | DJ23: 0.3 | DK23: 0.046 | DL23: 0.0377 | DM23: #N/A | DR23: -1
CQ24: 37104 | CR24: 0 | CS24: 0.027199074 | CT24: 1 | CV24: 37104 | CW24: 0.001019368 | CX24: 0.028213166 | CY24: 0.026232949 | DA24: 37104 | DB24: 0.0016094421 | DC24: 0.026967529 | DE24: 37104 | DF24: 0.0020512821 | DG24: 0.021920668 | DI24: 37104 | DJ24: 0.3 | DK24: 0.049 | DL24: 0.0365 | DM24: #N/A | DR24: -1
CQ25: 37135 | CR25: 0.003945885 | CS25: 0.026482441 | CT25: 1 | CV25: 37135 | CW25: 0.0020366599 | CX25: 0.026014568 | CY25: 0.028154327 | DA25: 37135 | DB25: 0.0021424746 | DC25: 0.026330225 | DE25: 37135 | DF25: 0.0020470829 | DG25: 0.021875 | DI25: 37135 | DJ25: 0.3 | DK25: 0.05 | DL25: 0.0307 | DM25: #N/A | DR25: -1
CQ26: 37165 | CR26: -0.0028074116 | CS26: 0.021264368 | CT26: 1 | CV26: 37165 | CW26: -0.0030487805 | CX26: 0.018691589 | CY26: 0.014583333 | DA26: 37165 | DB26: 0.0016034206 | DC26: 0.026258206 | DE26: 37165 | DF26: 0 | DG26: 0.019771072 | DI26: 37165 | DJ26: 0.3 | DK26: 0.053 | DL26: 0.0249 | DM26: #N/A | DR26: -1
B27: US Core CPI | E27: Start Date | F27: 36526 | H27: End Date | I27: =TODAY() -> 46280 | T27: Canadian Core CPI | X27: Start Date | Y27: 36526 | AA27: End Date | AB27: =TODAY() -> 46280 | CQ27: 37196 | CR27: -0.00056306306 | CS27: 0.018954624 | CT27: 1 | CV27: 37196 | CW27: -0.0071355759 | CX27: 0.0062111801 | CY27: -0.024922118 | DA27: 37196 | DB27: 0.0037353255 | DC27: 0.027868852 | DE27: 37196 | DF27: -0.0010214505 | DG27: 0.016632017 | DI27: 37196 | DJ27: 0.3 | DK27: 0.055 | DL27: 0.0209 | DM27: #N/A | DR27: -1
CQ28: 37226 | CR28: -0.00056338028 | CS28: 0.015517241 | CT28: #N/A | CV28: 37226 | CW28: 0.0030800821 | CX28: 0.0072388831 | CY28: -0.0093457944 | DA28: 37226 | DB28: 0.0015948963 | DC28: 0.027352298 | DE28: 37226 | DF28: 0.0020449898 | DG28: 0.015592516 | DI28: 37226 | DJ28: #N/A | DK28: 0.057 | DL28: 0.0182 | DM28: #N/A | DR28: #N/A
CQ29: 37257 | CR29: 0.0016910936 | CS29: 0.011422045 | CT29: #N/A | CV29: 37257 | CW29: 0.0040941658 | CX29: 0.013499481 | CY29: 0.035331906 | DA29: 37257 | DB29: 0.0015923567 | DC29: 0.025613079 | DE29: 37257 | DF29: 0.0010204082 | DG29: 0.016666667 | DI29: 37257 | DJ29: #N/A | DK29: 0.057 | DL29: 0.0173 | DM29: #N/A | DR29: #N/A
CQ30: 37288 | CR30: 0.0016882386 | CS30: 0.011376564 | CT30: #N/A | CV30: 37288 | CW30: 0.003058104 | CX30: 0.01446281 | CY30: 0.015673981 | DA30: 37288 | DB30: 0.0021197668 | DC30: 0.026030369 | DE30: 37288 | DF30: 0.003058104 | DG30: 0.01761658 | DI30: 37288 | DJ30: #N/A | DK30: 0.057 | DL30: 0.0174 | DM30: #N/A | DR30: #N/A
CQ31: 37316 | CR31: 0.0028089888 | CS31: 0.014755959 | CT31: #N/A | CV31: 37316 | CW31: 0.0040650407 | CX31: 0.01853759 | CY31: 0.019874477 | DA31: 37316 | DB31: 0.00052882073 | DC31: 0.024284943 | DE31: 37316 | DF31: 0.0030487805 | DG31: 0.02173913 | DI31: 37316 | DJ31: #N/A | DK31: 0.057 | DL31: 0.0173 | DM31: #N/A | DR31: #N/A
CQ32: 37347 | CR32: 0.0044817927 | CS32: 0.016393443 | CT32: #N/A | CV32: 37347 | CW32: 0.0070850202 | CX32: 0.017382413 | CY32: 0.034482759 | DA32: 37347 | DB32: 0.0026427061 | DC32: 0.025323276 | DE32: 37347 | DF32: 0.0050658561 | DG32: 0.022680412 | DI32: 37347 | DJ32: #N/A | DK32: 0.059 | DL32: 0.0175 | DM32: #N/A | DR32: #N/A
CQ33: 37377 | CR33: 0.001115449 | CS33: 0.01181767 | CT33: #N/A | CV33: 37377 | CW33: -0.0010050251 | CX33: 0.011156187 | CY33: 0.002016129 | DA33: 37377 | DB33: 0.0015814444 | DC33: 0.025336927 | DE33: 37377 | DF33: 0.0030241935 | DG33: 0.023638232 | DI33: 37377 | DJ33: #N/A | DK33: 0.058 | DL33: 0.0175 | DM33: #N/A | DR33: #N/A
CQ34: 37408 | CR34: 0.00055710306 | CS34: 0.010674157 | CT34: #N/A | CV34: 37408 | CW34: 0.0020120724 | CX34: 0.012158055 | CY34: 0.0040201005 | DA34: 37408 | DB34: 0.0010526316 | DC34: 0.022592792 | DE34: 37408 | DF34: 0.0040201005 | DG34: 0.026694045 | DI34: 37408 | DJ34: #N/A | DK34: 0.058 | DL34: 0.0175 | DM34: #N/A | DR34: #N/A
CQ35: 37438 | CR35: 0.0022271715 | CS35: 0.014647887 | CT35: #N/A | CV35: 37438 | CW35: 0.0070281124 | CX35: 0.021341463 | CY35: 0.020429009 | DA35: 37438 | DB35: 0.0015772871 | DC35: 0.022019334 | DE35: 37438 | DF35: 0.005005005 | DG35: 0.028629857 | DI35: 37438 | DJ35: #N/A | DK35: 0.058 | DL35: 0.0173 | DM35: #N/A | DR35: #N/A
CQ36: 37469 | CR36: 0.0027777778 | CS36: 0.018028169 | CT36: #N/A | CV36: 37469 | CW36: 0.0039880359 | CX36: 0.025406504 | CY36: 0.023517382 | DA36: 37469 | DB36: 0.0031496063 | DC36: 0.02357985 | DE36: 37469 | DF36: 0.0029880478 | DG36: 0.030643514 | DI36: 37469 | DJ36: #N/A | DK36: 0.057 | DL36: 0.0174 | DM36: #N/A | DR36: #N/A
CQ37: 37500 | CR37: 0.0016620499 | CS37: 0.015143017 | CT37: #N/A | CV37: 37500 | CW37: 0.00099304866 | CX37: 0.023326572 | CY37: 0.028397566 | DA37: 37500 | DB37: 0.0010465725 | DC37: 0.022447889 | DE37: 37500 | DF37: 0.0019860973 | DG37: 0.029561672 | DI37: 37500 | DJ37: #N/A | DK37: 0.057 | DL37: 0.0175 | DM37: #N/A | DR37: #N/A
CQ38: 37530 | CR38: 0.0022123894 | CS38: 0.020258863 | CT38: #N/A | CV38: 37530 | CW38: 0.0049603175 | CX38: 0.031600408 | CY38: 0.052361396 | DA38: 37530 | DB38: 0.0010454783 | DC38: 0.02238806 | DE38: 37530 | DF38: 0.0019821606 | DG38: 0.032653061 | DI38: 37530 | DJ38: #N/A | DK38: 0.057 | DL38: 0.0175 | DM38: #N/A | DR38: #N/A
CQ39: 37561 | CR39: 0.0016556291 | CS39: 0.021984216 | CT39: #N/A | CV39: 37561 | CW39: 0.0029615005 | CX39: 0.044238683 | CY39: 0.096911608 | DA39: 37561 | DB39: 0.0020887728 | DC39: 0.019670388 | DE39: 37561 | DF39: 0.0029673591 | DG39: 0.036809816 | DI39: 37561 | DJ39: #N/A | DK39: 0.059 | DL39: 0.0134 | DM39: #N/A | DR39: #N/A
... CQ100: 39417 | CR100: 0.0028980146 | CS100: 0.040812686 | CT100: #N/A | CV100: 39417 | CW100: 0.0035650624 | CX100: 0.023765996 | CY100: 0.041155867 | DA100: 39417 | DB100: 0.0023887896 | DC100: 0.024389773 | DE100: 39417 | DF100: 0.00091407678 | DG100: 0.016728625 | DI100: 39417 | DJ100: #N/A | DK100: 0.05 | DL100: 0.0424 | DM100: #N/A | DR100: #N/A
CQ101: 39448 | CR101: 0.0034477051 | CS101: 0.04280294 | CT101: 1 | CV101: 39448 | CW101: -0.0017761989 | CX101: 0.021937843 | CY101: 0.035745423 | DA101: 39448 | DB101: 0.0028287548 | DC101: 0.024657587 | DE101: 39448 | DF101: -0.00091324201 | DG101: 0.013011152 | DI101: 39448 | DJ101: 0.3 | DK101: 0.05 | DL101: 0.0394 | DM101: #N/A | DR101: -1
CQ102: 39479 | CR102: 0.0024178269 | CS102: 0.040265554 | CT102: 1 | CV102: 39479 | CW102: 0.0017793594 | CX102: 0.01814882 | CY102: 0.034782609 | DA102: 39479 | DB102: 0.0007858877 | DC102: 0.022734229 | DE102: 39479 | DF102: 0.0018281536 | DG102: 0.012962963 | DI102: 39479 | DJ102: 0.3 | DK102: 0.049 | DL102: 0.0298 | DM102: #N/A | DR102: -1
CQ103: 39508 | CR103: 0.0035780278 | CS103: 0.039814562 | CT103: 1 | CV103: 39508 | CW103: 0.0017761989 | CX103: 0.01350135 | CY103: 0.029209622 | DA103: 39508 | DB103: 0.0022483044 | DC103: 0.023546729 | DE103: 39508 | DF103: 0.00091240876 | DG103: 0.010138249 | DI103: 39508 | DJ103: 0.3 | DK103: 0.051 | DL103: 0.0261 | DM103: #N/A | DR103: -1
...
